Workbook

Sheet Leeme
A1: Panel país-año Latinobarómetro para regresión (MCO)
A3: Fuente: exportaciones de la herramienta de análisis online de Latinobarómetro (porcentajes ya ponderados). Archivos: data/online/apoyo_democracia.xlsx y data/online/grupos_poderosos.xlsx.
A5: HOJAS
A6: Datos: todas las tablas exportadas en formato largo (una fila por variable, país, año y categoría). Valores copiados de la herramienta online (texto azul).
A7: Categorias: % de cada categoría por país-año, calculado con SUMIFS sobre Datos.
A8: Gini: COMPLETAR las celdas amarillas (Gini 0-100 y fuente, p. ej. Banco Mundial / SEDLAC).
A9: Corrupcion: Índice de Percepción de la Corrupción (Transparency International). Dos versiones: 'CPI escala 0-10 (empalmado)' = datahub.io hasta 2011 + global HDX / 10 desde 2012; 'CPI 0-100 (desde 2012)' = global HDX sin transformar; 'CPI 0-100 empalmado por regresión' = hasta 2011 a + b x datahub, con a y b estimados en la hoja Puente_CPI (176 países, CPI 2012 sobre CPI 2011), y desde 2012 global HDX.
A10: Puente_CPI: datos de los 176 países con CPI 2011 (método antiguo) y 2012 (método nuevo) y los coeficientes del empalme (INTERSECCION.EJE, PENDIENTE, R2).
A11: Panel_A: variables con el criterio A = % de la categoría sobre el total (incluye NS/NR). Robustez.
A12: Panel_B: variables con el criterio B = % sobre respuestas válidas (excluye NS/NR). Modelo principal.
A14: DEFINICIONES
A15: Y = % 'La democracia es preferible a cualquier otra forma de gobierno'. B: Democracia / (Democracia + Gobierno autoritario + Da lo mismo).
... A31: Colores: azul = dato de origen; verde = vínculo a otra hoja; negro = cálculo; amarillo = completar.

Sheet Datos
A1: Variable | B1: País | C1: Año | D1: Categoría | E1: Porcentaje | F1: N (casos)
A2: Apoyo democracia | B2: Argentina | C2: 1995 | D2: Democracia | E2: 0.755 | F2: 1200
A3: Apoyo democracia | B3: Argentina | C3: 1995 | D3: Gobierno Autoritario | E3: 0.108 | F3: 1200
A4: Apoyo democracia | B4: Argentina | C4: 1995 | D4: Da lo mismo | E4: 0.06 | F4: 1200
A5: Apoyo democracia | B5: Argentina | C5: 1995 | D5: No sabe | E5: 0.063 | F5: 1200
A6: Apoyo democracia | B6: Argentina | C6: 1995 | D6: No contesta | E6: 0.014 | F6: 1200
A7: Apoyo democracia | B7: Argentina | C7: 1996 | D7: Democracia | E7: 0.712 | F7: 1199
A8: Apoyo democracia | B8: Argentina | C8: 1996 | D8: Gobierno Autoritario | E8: 0.147 | F8: 1199
A9: Apoyo democracia | B9: Argentina | C9: 1996 | D9: Da lo mismo | E9: 0.112 | F9: 1199
A10: Apoyo democracia | B10: Argentina | C10: 1996 | D10: No sabe | E10: 0.023 | F10: 1199
A11: Apoyo democracia | B11: Argentina | C11: 1996 | D11: No contesta | E11: 0.007 | F11: 1199
A12: Apoyo democracia | B12: Argentina | C12: 1997 | D12: Democracia | E12: 0.747 | F12: 1196
A13: Apoyo democracia | B13: Argentina | C13: 1997 | D13: Gobierno Autoritario | E13: 0.148 | F13: 1196
... A2587: Grupos poderosos | B2587: Venezuela | C2587: 2024 | D2587: No sabe; no responde | E2587: 0.033 | F2587: 1200

Sheet Categorias
A1: Variable → | C1: Apoyo democracia | D1: Apoyo democracia | E1: Apoyo democracia | F1: Apoyo democracia | G1: Apoyo democracia | H1: Grupos poderosos | I1: Grupos poderosos | J1: Grupos poderosos
A2: País | B2: Año | C2: Democracia | D2: Gobierno Autoritario | E2: Da lo mismo | F2: No sabe | G2: No contesta | H2: Grupos poderosos en su propio beneficio | I2: Para el bien de todo el pueblo | J2: No sabe; no responde
A3: Argentina | B3: 1995 | C3: =IF(COUNTIFS(Datos!$A$2:$A$5000,C$1,Datos!$B$2:$B$5000,$A3,Datos!$C$2:$C$5000,$B3,Datos!$D$2:$D$5000,C$2)=0,"",SUMIFS(Datos!$E$2:$E$5000,Datos!$A$2:$A$5000,C$1,Datos!$B$2:$B$5000,$A3,Datos!$C$2:$C$5000,$B3,Datos!$D$2:$D$5000,C$2)) | D3: =IF(COUNTIFS(Datos!$A$2:$A$5000,D$1,Datos!$B$2:$B$5000,$A3,Datos!$C$2:$C$5000,$B3,Datos!$D$2:$D$5000,D$2)=0,"",SUMIFS(Datos!$E$2:$E$5000,Datos!$A$2:$A$5000,D$1,Datos!$B$2:$B$5000,$A3,Datos!$C$2:$C$5000,$B3,Datos!$D$2:$D$5000,D$2)) | E3: =IF(COUNTIFS(Datos!$A$2:$A$5000,E$1,Datos!$B$2:$B$5000,$A3,Datos!$C$2:$C$5000,$B3,Datos!$D$2:$D$5000,E$2)=0,"",SUMIFS(Datos!$E$2:$E$5000,Datos!$A$2:$A$5000,E$1,Datos!$B$2:$B$5000,$A3,Datos!$C$2:$C$5000,$B3,Datos!$D$2:$D$5000,E$2)) | F3: =IF(COUNTIFS(Datos!$A$2:$A$5000,F$1,Datos!$B$2:$B$5000,$A3,Datos!$C$2:$C$5000,$B3,Datos!$D$2:$D$5000,F$2)=0,"",SUMIFS(Datos!$E$2:$E$5000,Datos!$A$2:$A$5000,F$1,Datos!$B$2:$B$5000,$A3,Datos!$C$2:$C$5000,$B3,Datos!$D$2:$D$5000,F$2)) | G3: =IF(COUNTIFS(Datos!$A$2:$A$5000,G$1,Datos!$B$2:$B$5000,$A3,Datos!$C$2:$C$5000,$B3,Datos!$D$2:$D$5000,G$2)=0,"",SUMIFS(Datos!$E$2:$E$5000,Datos!$A$2:$A$5000,G$1,Datos!$B$2:$B$5000,$A3,Datos!$C$2:$C$5000,$B3,Datos!$D$2:$D$5000,G$2)) | H3: =IF(COUNTIFS(Datos!$A$2:$A$5000,H$1,Datos!$B$2:$B$5000,$A3,Datos!$C$2:$C$5000,$B3,Datos!$D$2:$D$5000,H$2)=0,"",SUMIFS(Datos!$E$2:$E$5000,Datos!$A$2:$A$5000,H$1,Datos!$B$2:$B$5000,$A3,Datos!$C$2:$C$5000,$B3,Datos!$D$2:$D$5000,H$2)) | I3: =IF(COUNTIFS(Datos!$A$2:$A$5000,I$1,Datos!$B$2:$B$5000,$A3,Datos!$C$2:$C$5000,$B3,Datos!$D$2:$D$5000,I$2)=0,"",SUMIFS(Datos!$E$2:$E$5000,Datos!$A$2:$A$5000,I$1,Datos!$B$2:$B$5000,$A3,Datos!$C$2:$C$5000,$B3,Datos!$D$2:$D$5000,I$2)) | J3: =IF(COUNTIFS(Datos!$A$2:$A$5000,J$1,Datos!$B$2:$B$5000,$A3,Datos!$C$2:$C$5000,$B3,Datos!$D$2:$D$5000,J$2)=0,"",SUMIFS(Datos!$E$2:$E$5000,Datos!$A$2:$A$5000,J$1,Datos!$B$2:$B$5000,$A3,Datos!$C$2:$C$5000,$B3,Datos!$D$2:$D$5000,J$2))
A4: Argentina | B4: 1996 | C4: =IF(COUNTIFS(Datos!$A$2:$A$5000,C$1,Datos!$B$2:$B$5000,$A4,Datos!$C$2:$C$5000,$B4,Datos!$D$2:$D$5000,C$2)=0,"",SUMIFS(Datos!$E$2:$E$5000,Datos!$A$2:$A$5000,C$1,Datos!$B$2:$B$5000,$A4,Datos!$C$2:$C$5000,$B4,Datos!$D$2:$D$5000,C$2)) | D4: =IF(COUNTIFS(Datos!$A$2:$A$5000,D$1,Datos!$B$2:$B$5000,$A4,Datos!$C$2:$C$5000,$B4,Datos!$D$2:$D$5000,D$2)=0,"",SUMIFS(Datos!$E$2:$E$5000,Datos!$A$2:$A$5000,D$1,Datos!$B$2:$B$5000,$A4,Datos!$C$2:$C$5000,$B4,Datos!$D$2:$D$5000,D$2)) | E4: =IF(COUNTIFS(Datos!$A$2:$A$5000,E$1,Datos!$B$2:$B$5000,$A4,Datos!$C$2:$C$5000,$B4,Datos!$D$2:$D$5000,E$2)=0,"",SUMIFS(Datos!$E$2:$E$5000,Datos!$A$2:$A$5000,E$1,Datos!$B$2:$B$5000,$A4,Datos!$C$2:$C$5000,$B4,Datos!$D$2:$D$5000,E$2)) | F4: =IF(COUNTIFS(Datos!$A$2:$A$5000,F$1,Datos!$B$2:$B$5000,$A4,Datos!$C$2:$C$5000,$B4,Datos!$D$2:$D$5000,F$2)=0,"",SUMIFS(Datos!$E$2:$E$5000,Datos!$A$2:$A$5000,F$1,Datos!$B$2:$B$5000,$A4,Datos!$C$2:$C$5000,$B4,Datos!$D$2:$D$5000,F$2)) | G4: =IF(COUNTIFS(Datos!$A$2:$A$5000,G$1,Datos!$B$2:$B$5000,$A4,Datos!$C$2:$C$5000,$B4,Datos!$D$2:$D$5000,G$2)=0,"",SUMIFS(Datos!$E$2:$E$5000,Datos!$A$2:$A$5000,G$1,Datos!$B$2:$B$5000,$A4,Datos!$C$2:$C$5000,$B4,Datos!$D$2:$D$5000,G$2)) | H4: =IF(COUNTIFS(Datos!$A$2:$A$5000,H$1,Datos!$B$2:$B$5000,$A4,Datos!$C$2:$C$5000,$B4,Datos!$D$2:$D$5000,H$2)=0,"",SUMIFS(Datos!$E$2:$E$5000,Datos!$A$2:$A$5000,H$1,Datos!$B$2:$B$5000,$A4,Datos!$C$2:$C$5000,$B4,Datos!$D$2:$D$5000,H$2)) | I4: =IF(COUNTIFS(Datos!$A$2:$A$5000,I$1,Datos!$B$2:$B$5000,$A4,Datos!$C$2:$C$5000,$B4,Datos!$D$2:$D$5000,I$2)=0,"",SUMIFS(Datos!$E$2:$E$5000,Datos!$A$2:$A$5000,I$1,Datos!$B$2:$B$5000,$A4,Datos!$C$2:$C$5000,$B4,Datos!$D$2:$D$5000,I$2)) | J4: =IF(COUNTIFS(Datos!$A$2:$A$5000,J$1,Datos!$B$2:$B$5000,$A4,Datos!$C$2:$C$5000,$B4,Datos!$D$2:$D$5000,J$2)=0,"",SUMIFS(Datos!$E$2:$E$5000,Datos!$A$2:$A$5000,J$1,Datos!$B$2:$B$5000,$A4,Datos!$C$2:$C$5000,$B4,Datos!$D$2:$D$5000,J$2))
A5: Argentina | B5: 1997 | C5: =IF(COUNTIFS(Datos!$A$2:$A$5000,C$1,Datos!$B$2:$B$5000,$A5,Datos!$C$2:$C$5000,$B5,Datos!$D$2:$D$5000,C$2)=0,"",SUMIFS(Datos!$E$2:$E$5000,Datos!$A$2:$A$5000,C$1,Datos!$B$2:$B$5000,$A5,Datos!$C$2:$C$5000,$B5,Datos!$D$2:$D$5000,C$2)) | D5: =IF(COUNTIFS(Datos!$A$2:$A$5000,D$1,Datos!$B$2:$B$5000,$A5,Datos!$C$2:$C$5000,$B5,Datos!$D$2:$D$5000,D$2)=0,"",SUMIFS(Datos!$E$2:$E$5000,Datos!$A$2:$A$5000,D$1,Datos!$B$2:$B$5000,$A5,Datos!$C$2:$C$5000,$B5,Datos!$D$2:$D$5000,D$2)) | E5: =IF(COUNTIFS(Datos!$A$2:$A$5000,E$1,Datos!$B$2:$B$5000,$A5,Datos!$C$2:$C$5000,$B5,Datos!$D$2:$D$5000,E$2)=0,"",SUMIFS(Datos!$E$2:$E$5000,Datos!$A$2:$A$5000,E$1,Datos!$B$2:$B$5000,$A5,Datos!$C$2:$C$5000,$B5,Datos!$D$2:$D$5000,E$2)) | F5: =IF(COUNTIFS(Datos!$A$2:$A$5000,F$1,Datos!$B$2:$B$5000,$A5,Datos!$C$2:$C$5000,$B5,Datos!$D$2:$D$5000,F$2)=0,"",SUMIFS(Datos!$E$2:$E$5000,Datos!$A$2:$A$5000,F$1,Datos!$B$2:$B$5000,$A5,Datos!$C$2:$C$5000,$B5,Datos!$D$2:$D$5000,F$2)) | G5: =IF(COUNTIFS(Datos!$A$2:$A$5000,G$1,Datos!$B$2:$B$5000,$A5,Datos!$C$2:$C$5000,$B5,Datos!$D$2:$D$5000,G$2)=0,"",SUMIFS(Datos!$E$2:$E$5000,Datos!$A$2:$A$5000,G$1,Datos!$B$2:$B$5000,$A5,Datos!$C$2:$C$5000,$B5,Datos!$D$2:$D$5000,G$2)) | H5: =IF(COUNTIFS(Datos!$A$2:$A$5000,H$1,Datos!$B$2:$B$5000,$A5,Datos!$C$2:$C$5000,$B5,Datos!$D$2:$D$5000,H$2)=0,"",SUMIFS(Datos!$E$2:$E$5000,Datos!$A$2:$A$5000,H$1,Datos!$B$2:$B$5000,$A5,Datos!$C$2:$C$5000,$B5,Datos!$D$2:$D$5000,H$2)) | I5: =IF(COUNTIFS(Datos!$A$2:$A$5000,I$1,Datos!$B$2:$B$5000,$A5,Datos!$C$2:$C$5000,$B5,Datos!$D$2:$D$5000,I$2)=0,"",SUMIFS(Datos!$E$2:$E$5000,Datos!$A$2:$A$5000,I$1,Datos!$B$2:$B$5000,$A5,Datos!$C$2:$C$5000,$B5,Datos!$D$2:$D$5000,I$2)) | J5: =IF(COUNTIFS(Datos!$A$2:$A$5000,J$1,Datos!$B$2:$B$5000,$A5,Datos!$C$2:$C$5000,$B5,Datos!$D$2:$D$5000,J$2)=0,"",SUMIFS(Datos!$E$2:$E$5000,Datos!$A$2:$A$5000,J$1,Datos!$B$2:$B$5000,$A5,Datos!$C$2:$C$5000,$B5,Datos!$D$2:$D$5000,J$2))
A6: Argentina | B6: 1998 | C6: =IF(COUNTIFS(Datos!$A$2:$A$5000,C$1,Datos!$B$2:$B$5000,$A6,Datos!$C$2:$C$5000,$B6,Datos!$D$2:$D$5000,C$2)=0,"",SUMIFS(Datos!$E$2:$E$5000,Datos!$A$2:$A$5000,C$1,Datos!$B$2:$B$5000,$A6,Datos!$C$2:$C$5000,$B6,Datos!$D$2:$D$5000,C$2)) | D6: =IF(COUNTIFS(Datos!$A$2:$A$5000,D$1,Datos!$B$2:$B$5000,$A6,Datos!$C$2:$C$5000,$B6,Datos!$D$2:$D$5000,D$2)=0,"",SUMIFS(Datos!$E$2:$E$5000,Datos!$A$2:$A$5000,D$1,Datos!$B$2:$B$5000,$A6,Datos!$C$2:$C$5000,$B6,Datos!$D$2:$D$5000,D$2)) | E6: =IF(COUNTIFS(Datos!$A$2:$A$5000,E$1,Datos!$B$2:$B$5000,$A6,Datos!$C$2:$C$5000,$B6,Datos!$D$2:$D$5000,E$2)=0,"",SUMIFS(Datos!$E$2:$E$5000,Datos!$A$2:$A$5000,E$1,Datos!$B$2:$B$5000,$A6,Datos!$C$2:$C$5000,$B6,Datos!$D$2:$D$5000,E$2)) | F6: =IF(COUNTIFS(Datos!$A$2:$A$5000,F$1,Datos!$B$2:$B$5000,$A6,Datos!$C$2:$C$5000,$B6,Datos!$D$2:$D$5000,F$2)=0,"",SUMIFS(Datos!$E$2:$E$5000,Datos!$A$2:$A$5000,F$1,Datos!$B$2:$B$5000,$A6,Datos!$C$2:$C$5000,$B6,Datos!$D$2:$D$5000,F$2)) | G6: =IF(COUNTIFS(Datos!$A$2:$A$5000,G$1,Datos!$B$2:$B$5000,$A6,Datos!$C$2:$C$5000,$B6,Datos!$D$2:$D$5000,G$2)=0,"",SUMIFS(Datos!$E$2:$E$5000,Datos!$A$2:$A$5000,G$1,Datos!$B$2:$B$5000,$A6,Datos!$C$2:$C$5000,$B6,Datos!$D$2:$D$5000,G$2)) | H6: =IF(COUNTIFS(Datos!$A$2:$A$5000,H$1,Datos!$B$2:$B$5000,$A6,Datos!$C$2:$C$5000,$B6,Datos!$D$2:$D$5000,H$2)=0,"",SUMIFS(Datos!$E$2:$E$5000,Datos!$A$2:$A$5000,H$1,Datos!$B$2:$B$5000,$A6,Datos!$C$2:$C$5000,$B6,Datos!$D$2:$D$5000,H$2)) | I6: =IF(COUNTIFS(Datos!$A$2:$A$5000,I$1,Datos!$B$2:$B$5000,$A6,Datos!$C$2:$C$5000,$B6,Datos!$D$2:$D$5000,I$2)=0,"",SUMIFS(Datos!$E$2:$E$5000,Datos!$A$2:$A$5000,I$1,Datos!$B$2:$B$5000,$A6,Datos!$C$2:$C$5000,$B6,Datos!$D$2:$D$5000,I$2)) | J6: =IF(COUNTIFS(Datos!$A$2:$A$5000,J$1,Datos!$B$2:$B$5000,$A6,Datos!$C$2:$C$5000,$B6,Datos!$D$2:$D$5000,J$2)=0,"",SUMIFS(Datos!$E$2:$E$5000,Datos!$A$2:$A$5000,J$1,Datos!$B$2:$B$5000,$A6,Datos!$C$2:$C$5000,$B6,Datos!$D$2:$D$5000,J$2))
A7: Argentina | B7: 2000 | C7: =IF(COUNTIFS(Datos!$A$2:$A$5000,C$1,Datos!$B$2:$B$5000,$A7,Datos!$C$2:$C$5000,$B7,Datos!$D$2:$D$5000,C$2)=0,"",SUMIFS(Datos!$E$2:$E$5000,Datos!$A$2:$A$5000,C$1,Datos!$B$2:$B$5000,$A7,Datos!$C$2:$C$5000,$B7,Datos!$D$2:$D$5000,C$2)) | D7: =IF(COUNTIFS(Datos!$A$2:$A$5000,D$1,Datos!$B$2:$B$5000,$A7,Datos!$C$2:$C$5000,$B7,Datos!$D$2:$D$5000,D$2)=0,"",SUMIFS(Datos!$E$2:$E$5000,Datos!$A$2:$A$5000,D$1,Datos!$B$2:$B$5000,$A7,Datos!$C$2:$C$5000,$B7,Datos!$D$2:$D$5000,D$2)) | E7: =IF(COUNTIFS(Datos!$A$2:$A$5000,E$1,Datos!$B$2:$B$5000,$A7,Datos!$C$2:$C$5000,$B7,Datos!$D$2:$D$5000,E$2)=0,"",SUMIFS(Datos!$E$2:$E$5000,Datos!$A$2:$A$5000,E$1,Datos!$B$2:$B$5000,$A7,Datos!$C$2:$C$5000,$B7,Datos!$D$2:$D$5000,E$2)) | F7: =IF(COUNTIFS(Datos!$A$2:$A$5000,F$1,Datos!$B$2:$B$5000,$A7,Datos!$C$2:$C$5000,$B7,Datos!$D$2:$D$5000,F$2)=0,"",SUMIFS(Datos!$E$2:$E$5000,Datos!$A$2:$A$5000,F$1,Datos!$B$2:$B$5000,$A7,Datos!$C$2:$C$5000,$B7,Datos!$D$2:$D$5000,F$2)) | G7: =IF(COUNTIFS(Datos!$A$2:$A$5000,G$1,Datos!$B$2:$B$5000,$A7,Datos!$C$2:$C$5000,$B7,Datos!$D$2:$D$5000,G$2)=0,"",SUMIFS(Datos!$E$2:$E$5000,Datos!$A$2:$A$5000,G$1,Datos!$B$2:$B$5000,$A7,Datos!$C$2:$C$5000,$B7,Datos!$D$2:$D$5000,G$2)) | H7: =IF(COUNTIFS(Datos!$A$2:$A$5000,H$1,Datos!$B$2:$B$5000,$A7,Datos!$C$2:$C$5000,$B7,Datos!$D$2:$D$5000,H$2)=0,"",SUMIFS(Datos!$E$2:$E$5000,Datos!$A$2:$A$5000,H$1,Datos!$B$2:$B$5000,$A7,Datos!$C$2:$C$5000,$B7,Datos!$D$2:$D$5000,H$2)) | I7: =IF(COUNTIFS(Datos!$A$2:$A$5000,I$1,Datos!$B$2:$B$5000,$A7,Datos!$C$2:$C$5000,$B7,Datos!$D$2:$D$5000,I$2)=0,"",SUMIFS(Datos!$E$2:$E$5000,Datos!$A$2:$A$5000,I$1,Datos!$B$2:$B$5000,$A7,Datos!$C$2:$C$5000,$B7,Datos!$D$2:$D$5000,I$2)) | J7: =IF(COUNTIFS(Datos!$A$2:$A$5000,J$1,Datos!$B$2:$B$5000,$A7,Datos!$C$2:$C$5000,$B7,Datos!$D$2:$D$5000,J$2)=0,"",SUMIFS(Datos!$E$2:$E$5000,Datos!$A$2:$A$5000,J$1,Datos!$B$2:$B$5000,$A7,Datos!$C$2:$C$5000,$B7,Datos!$D$2:$D$5000,J$2))
A8: Argentina | B8: 2001 | C8: =IF(COUNTIFS(Datos!$A$2:$A$5000,C$1,Datos!$B$2:$B$5000,$A8,Datos!$C$2:$C$5000,$B8,Datos!$D$2:$D$5000,C$2)=0,"",SUMIFS(Datos!$E$2:$E$5000,Datos!$A$2:$A$5000,C$1,Datos!$B$2:$B$5000,$A8,Datos!$C$2:$C$5000,$B8,Datos!$D$2:$D$5000,C$2)) | D8: =IF(COUNTIFS(Datos!$A$2:$A$5000,D$1,Datos!$B$2:$B$5000,$A8,Datos!$C$2:$C$5000,$B8,Datos!$D$2:$D$5000,D$2)=0,"",SUMIFS(Datos!$E$2:$E$5000,Datos!$A$2:$A$5000,D$1,Datos!$B$2:$B$5000,$A8,Datos!$C$2:$C$5000,$B8,Datos!$D$2:$D$5000,D$2)) | E8: =IF(COUNTIFS(Datos!$A$2:$A$5000,E$1,Datos!$B$2:$B$5000,$A8,Datos!$C$2:$C$5000,$B8,Datos!$D$2:$D$5000,E$2)=0,"",SUMIFS(Datos!$E$2:$E$5000,Datos!$A$2:$A$5000,E$1,Datos!$B$2:$B$5000,$A8,Datos!$C$2:$C$5000,$B8,Datos!$D$2:$D$5000,E$2)) | F8: =IF(COUNTIFS(Datos!$A$2:$A$5000,F$1,Datos!$B$2:$B$5000,$A8,Datos!$C$2:$C$5000,$B8,Datos!$D$2:$D$5000,F$2)=0,"",SUMIFS(Datos!$E$2:$E$5000,Datos!$A$2:$A$5000,F$1,Datos!$B$2:$B$5000,$A8,Datos!$C$2:$C$5000,$B8,Datos!$D$2:$D$5000,F$2)) | G8: =IF(COUNTIFS(Datos!$A$2:$A$5000,G$1,Datos!$B$2:$B$5000,$A8,Datos!$C$2:$C$5000,$B8,Datos!$D$2:$D$5000,G$2)=0,"",SUMIFS(Datos!$E$2:$E$5000,Datos!$A$2:$A$5000,G$1,Datos!$B$2:$B$5000,$A8,Datos!$C$2:$C$5000,$B8,Datos!$D$2:$D$5000,G$2)) | H8: =IF(COUNTIFS(Datos!$A$2:$A$5000,H$1,Datos!$B$2:$B$5000,$A8,Datos!$C$2:$C$5000,$B8,Datos!$D$2:$D$5000,H$2)=0,"",SUMIFS(Datos!$E$2:$E$5000,Datos!$A$2:$A$5000,H$1,Datos!$B$2:$B$5000,$A8,Datos!$C$2:$C$5000,$B8,Datos!$D$2:$D$5000,H$2)) | I8: =IF(COUNTIFS(Datos!$A$2:$A$5000,I$1,Datos!$B$2:$B$5000,$A8,Datos!$C$2:$C$5000,$B8,Datos!$D$2:$D$5000,I$2)=0,"",SUMIFS(Datos!$E$2:$E$5000,Datos!$A$2:$A$5000,I$1,Datos!$B$2:$B$5000,$A8,Datos!$C$2:$C$5000,$B8,Datos!$D$2:$D$5000,I$2)) | J8: =IF(COUNTIFS(Datos!$A$2:$A$5000,J$1,Datos!$B$2:$B$5000,$A8,Datos!$C$2:$C$5000,$B8,Datos!$D$2:$D$5000,J$2)=0,"",SUMIFS(Datos!$E$2:$E$5000,Datos!$A$2:$A$5000,J$1,Datos!$B$2:$B$5000,$A8,Datos!$C$2:$C$5000,$B8,Datos!$D$2:$D$5000,J$2))
A9: Argentina | B9: 2002 | C9: =IF(COUNTIFS(Datos!$A$2:$A$5000,C$1,Datos!$B$2:$B$5000,$A9,Datos!$C$2:$C$5000,$B9,Datos!$D$2:$D$5000,C$2)=0,"",SUMIFS(Datos!$E$2:$E$5000,Datos!$A$2:$A$5000,C$1,Datos!$B$2:$B$5000,$A9,Datos!$C$2:$C$5000,$B9,Datos!$D$2:$D$5000,C$2)) | D9: =IF(COUNTIFS(Datos!$A$2:$A$5000,D$1,Datos!$B$2:$B$5000,$A9,Datos!$C$2:$C$5000,$B9,Datos!$D$2:$D$5000,D$2)=0,"",SUMIFS(Datos!$E$2:$E$5000,Datos!$A$2:$A$5000,D$1,Datos!$B$2:$B$5000,$A9,Datos!$C$2:$C$5000,$B9,Datos!$D$2:$D$5000,D$2)) | E9: =IF(COUNTIFS(Datos!$A$2:$A$5000,E$1,Datos!$B$2:$B$5000,$A9,Datos!$C$2:$C$5000,$B9,Datos!$D$2:$D$5000,E$2)=0,"",SUMIFS(Datos!$E$2:$E$5000,Datos!$A$2:$A$5000,E$1,Datos!$B$2:$B$5000,$A9,Datos!$C$2:$C$5000,$B9,Datos!$D$2:$D$5000,E$2)) | F9: =IF(COUNTIFS(Datos!$A$2:$A$5000,F$1,Datos!$B$2:$B$5000,$A9,Datos!$C$2:$C$5000,$B9,Datos!$D$2:$D$5000,F$2)=0,"",SUMIFS(Datos!$E$2:$E$5000,Datos!$A$2:$A$5000,F$1,Datos!$B$2:$B$5000,$A9,Datos!$C$2:$C$5000,$B9,Datos!$D$2:$D$5000,F$2)) | G9: =IF(COUNTIFS(Datos!$A$2:$A$5000,G$1,Datos!$B$2:$B$5000,$A9,Datos!$C$2:$C$5000,$B9,Datos!$D$2:$D$5000,G$2)=0,"",SUMIFS(Datos!$E$2:$E$5000,Datos!$A$2:$A$5000,G$1,Datos!$B$2:$B$5000,$A9,Datos!$C$2:$C$5000,$B9,Datos!$D$2:$D$5000,G$2)) | H9: =IF(COUNTIFS(Datos!$A$2:$A$5000,H$1,Datos!$B$2:$B$5000,$A9,Datos!$C$2:$C$5000,$B9,Datos!$D$2:$D$5000,H$2)=0,"",SUMIFS(Datos!$E$2:$E$5000,Datos!$A$2:$A$5000,H$1,Datos!$B$2:$B$5000,$A9,Datos!$C$2:$C$5000,$B9,Datos!$D$2:$D$5000,H$2)) | I9: =IF(COUNTIFS(Datos!$A$2:$A$5000,I$1,Datos!$B$2:$B$5000,$A9,Datos!$C$2:$C$5000,$B9,Datos!$D$2:$D$5000,I$2)=0,"",SUMIFS(Datos!$E$2:$E$5000,Datos!$A$2:$A$5000,I$1,Datos!$B$2:$B$5000,$A9,Datos!$C$2:$C$5000,$B9,Datos!$D$2:$D$5000,I$2)) | J9: =IF(COUNTIFS(Datos!$A$2:$A$5000,J$1,Datos!$B$2:$B$5000,$A9,Datos!$C$2:$C$5000,$B9,Datos!$D$2:$D$5000,J$2)=0,"",SUMIFS(Datos!$E$2:$E$5000,Datos!$A$2:$A$5000,J$1,Datos!$B$2:$B$5000,$A9,Datos!$C$2:$C$5000,$B9,Datos!$D$2:$D$5000,J$2))
A10: Argentina | B10: 2003 | C10: =IF(COUNTIFS(Datos!$A$2:$A$5000,C$1,Datos!$B$2:$B$5000,$A10,Datos!$C$2:$C$5000,$B10,Datos!$D$2:$D$5000,C$2)=0,"",SUMIFS(Datos!$E$2:$E$5000,Datos!$A$2:$A$5000,C$1,Datos!$B$2:$B$5000,$A10,Datos!$C$2:$C$5000,$B10,Datos!$D$2:$D$5000,C$2)) | D10: =IF(COUNTIFS(Datos!$A$2:$A$5000,D$1,Datos!$B$2:$B$5000,$A10,Datos!$C$2:$C$5000,$B10,Datos!$D$2:$D$5000,D$2)=0,"",SUMIFS(Datos!$E$2:$E$5000,Datos!$A$2:$A$5000,D$1,Datos!$B$2:$B$5000,$A10,Datos!$C$2:$C$5000,$B10,Datos!$D$2:$D$5000,D$2)) | E10: =IF(COUNTIFS(Datos!$A$2:$A$5000,E$1,Datos!$B$2:$B$5000,$A10,Datos!$C$2:$C$5000,$B10,Datos!$D$2:$D$5000,E$2)=0,"",SUMIFS(Datos!$E$2:$E$5000,Datos!$A$2:$A$5000,E$1,Datos!$B$2:$B$5000,$A10,Datos!$C$2:$C$5000,$B10,Datos!$D$2:$D$5000,E$2)) | F10: =IF(COUNTIFS(Datos!$A$2:$A$5000,F$1,Datos!$B$2:$B$5000,$A10,Datos!$C$2:$C$5000,$B10,Datos!$D$2:$D$5000,F$2)=0,"",SUMIFS(Datos!$E$2:$E$5000,Datos!$A$2:$A$5000,F$1,Datos!$B$2:$B$5000,$A10,Datos!$C$2:$C$5000,$B10,Datos!$D$2:$D$5000,F$2)) | G10: =IF(COUNTIFS(Datos!$A$2:$A$5000,G$1,Datos!$B$2:$B$5000,$A10,Datos!$C$2:$C$5000,$B10,Datos!$D$2:$D$5000,G$2)=0,"",SUMIFS(Datos!$E$2:$E$5000,Datos!$A$2:$A$5000,G$1,Datos!$B$2:$B$5000,$A10,Datos!$C$2:$C$5000,$B10,Datos!$D$2:$D$5000,G$2)) | H10: =IF(COUNTIFS(Datos!$A$2:$A$5000,H$1,Datos!$B$2:$B$5000,$A10,Datos!$C$2:$C$5000,$B10,Datos!$D$2:$D$5000,H$2)=0,"",SUMIFS(Datos!$E$2:$E$5000,Datos!$A$2:$A$5000,H$1,Datos!$B$2:$B$5000,$A10,Datos!$C$2:$C$5000,$B10,Datos!$D$2:$D$5000,H$2)) | I10: =IF(COUNTIFS(Datos!$A$2:$A$5000,I$1,Datos!$B$2:$B$5000,$A10,Datos!$C$2:$C$5000,$B10,Datos!$D$2:$D$5000,I$2)=0,"",SUMIFS(Datos!$E$2:$E$5000,Datos!$A$2:$A$5000,I$1,Datos!$B$2:$B$5000,$A10,Datos!$C$2:$C$5000,$B10,Datos!$D$2:$D$5000,I$2)) | J10: =IF(COUNTIFS(Datos!$A$2:$A$5000,J$1,Datos!$B$2:$B$5000,$A10,Datos!$C$2:$C$5000,$B10,Datos!$D$2:$D$5000,J$2)=0,"",SUMIFS(Datos!$E$2:$E$5000,Datos!$A$2:$A$5000,J$1,Datos!$B$2:$B$5000,$A10,Datos!$C$2:$C$5000,$B10,Datos!$D$2:$D$5000,J$2))
A11: Argentina | B11: 2004 | C11: =IF(COUNTIFS(Datos!$A$2:$A$5000,C$1,Datos!$B$2:$B$5000,$A11,Datos!$C$2:$C$5000,$B11,Datos!$D$2:$D$5000,C$2)=0,"",SUMIFS(Datos!$E$2:$E$5000,Datos!$A$2:$A$5000,C$1,Datos!$B$2:$B$5000,$A11,Datos!$C$2:$C$5000,$B11,Datos!$D$2:$D$5000,C$2)) | D11: =IF(COUNTIFS(Datos!$A$2:$A$5000,D$1,Datos!$B$2:$B$5000,$A11,Datos!$C$2:$C$5000,$B11,Datos!$D$2:$D$5000,D$2)=0,"",SUMIFS(Datos!$E$2:$E$5000,Datos!$A$2:$A$5000,D$1,Datos!$B$2:$B$5000,$A11,Datos!$C$2:$C$5000,$B11,Datos!$D$2:$D$5000,D$2)) | E11: =IF(COUNTIFS(Datos!$A$2:$A$5000,E$1,Datos!$B$2:$B$5000,$A11,Datos!$C$2:$C$5000,$B11,Datos!$D$2:$D$5000,E$2)=0,"",SUMIFS(Datos!$E$2:$E$5000,Datos!$A$2:$A$5000,E$1,Datos!$B$2:$B$5000,$A11,Datos!$C$2:$C$5000,$B11,Datos!$D$2:$D$5000,E$2)) | F11: =IF(COUNTIFS(Datos!$A$2:$A$5000,F$1,Datos!$B$2:$B$5000,$A11,Datos!$C$2:$C$5000,$B11,Datos!$D$2:$D$5000,F$2)=0,"",SUMIFS(Datos!$E$2:$E$5000,Datos!$A$2:$A$5000,F$1,Datos!$B$2:$B$5000,$A11,Datos!$C$2:$C$5000,$B11,Datos!$D$2:$D$5000,F$2)) | G11: =IF(COUNTIFS(Datos!$A$2:$A$5000,G$1,Datos!$B$2:$B$5000,$A11,Datos!$C$2:$C$5000,$B11,Datos!$D$2:$D$5000,G$2)=0,"",SUMIFS(Datos!$E$2:$E$5000,Datos!$A$2:$A$5000,G$1,Datos!$B$2:$B$5000,$A11,Datos!$C$2:$C$5000,$B11,Datos!$D$2:$D$5000,G$2)) | H11: =IF(COUNTIFS(Datos!$A$2:$A$5000,H$1,Datos!$B$2:$B$5000,$A11,Datos!$C$2:$C$5000,$B11,Datos!$D$2:$D$5000,H$2)=0,"",SUMIFS(Datos!$E$2:$E$5000,Datos!$A$2:$A$5000,H$1,Datos!$B$2:$B$5000,$A11,Datos!$C$2:$C$5000,$B11,Datos!$D$2:$D$5000,H$2)) | I11: =IF(COUNTIFS(Datos!$A$2:$A$5000,I$1,Datos!$B$2:$B$5000,$A11,Datos!$C$2:$C$5000,$B11,Datos!$D$2:$D$5000,I$2)=0,"",SUMIFS(Datos!$E$2:$E$5000,Datos!$A$2:$A$5000,I$1,Datos!$B$2:$B$5000,$A11,Datos!$C$2:$C$5000,$B11,Datos!$D$2:$D$5000,I$2)) | J11: =IF(COUNTIFS(Datos!$A$2:$A$5000,J$1,Datos!$B$2:$B$5000,$A11,Datos!$C$2:$C$5000,$B11,Datos!$D$2:$D$5000,J$2)=0,"",SUMIFS(Datos!$E$2:$E$5000,Datos!$A$2:$A$5000,J$1,Datos!$B$2:$B$5000,$A11,Datos!$C$2:$C$5000,$B11,Datos!$D$2:$D$5000,J$2))
A12: Argentina | B12: 2005 | C12: =IF(COUNTIFS(Datos!$A$2:$A$5000,C$1,Datos!$B$2:$B$5000,$A12,Datos!$C$2:$C$5000,$B12,Datos!$D$2:$D$5000,C$2)=0,"",SUMIFS(Datos!$E$2:$E$5000,Datos!$A$2:$A$5000,C$1,Datos!$B$2:$B$5000,$A12,Datos!$C$2:$C$5000,$B12,Datos!$D$2:$D$5000,C$2)) | D12: =IF(COUNTIFS(Datos!$A$2:$A$5000,D$1,Datos!$B$2:$B$5000,$A12,Datos!$C$2:$C$5000,$B12,Datos!$D$2:$D$5000,D$2)=0,"",SUMIFS(Datos!$E$2:$E$5000,Datos!$A$2:$A$5000,D$1,Datos!$B$2:$B$5000,$A12,Datos!$C$2:$C$5000,$B12,Datos!$D$2:$D$5000,D$2)) | E12: =IF(COUNTIFS(Datos!$A$2:$A$5000,E$1,Datos!$B$2:$B$5000,$A12,Datos!$C$2:$C$5000,$B12,Datos!$D$2:$D$5000,E$2)=0,"",SUMIFS(Datos!$E$2:$E$5000,Datos!$A$2:$A$5000,E$1,Datos!$B$2:$B$5000,$A12,Datos!$C$2:$C$5000,$B12,Datos!$D$2:$D$5000,E$2)) | F12: =IF(COUNTIFS(Datos!$A$2:$A$5000,F$1,Datos!$B$2:$B$5000,$A12,Datos!$C$2:$C$5000,$B12,Datos!$D$2:$D$5000,F$2)=0,"",SUMIFS(Datos!$E$2:$E$5000,Datos!$A$2:$A$5000,F$1,Datos!$B$2:$B$5000,$A12,Datos!$C$2:$C$5000,$B12,Datos!$D$2:$D$5000,F$2)) | G12: =IF(COUNTIFS(Datos!$A$2:$A$5000,G$1,Datos!$B$2:$B$5000,$A12,Datos!$C$2:$C$5000,$B12,Datos!$D$2:$D$5000,G$2)=0,"",SUMIFS(Datos!$E$2:$E$5000,Datos!$A$2:$A$5000,G$1,Datos!$B$2:$B$5000,$A12,Datos!$C$2:$C$5000,$B12,Datos!$D$2:$D$5000,G$2)) | H12: =IF(COUNTIFS(Datos!$A$2:$A$5000,H$1,Datos!$B$2:$B$5000,$A12,Datos!$C$2:$C$5000,$B12,Datos!$D$2:$D$5000,H$2)=0,"",SUMIFS(Datos!$E$2:$E$5000,Datos!$A$2:$A$5000,H$1,Datos!$B$2:$B$5000,$A12,Datos!$C$2:$C$5000,$B12,Datos!$D$2:$D$5000,H$2)) | I12: =IF(COUNTIFS(Datos!$A$2:$A$5000,I$1,Datos!$B$2:$B$5000,$A12,Datos!$C$2:$C$5000,$B12,Datos!$D$2:$D$5000,I$2)=0,"",SUMIFS(Datos!$E$2:$E$5000,Datos!$A$2:$A$5000,I$1,Datos!$B$2:$B$5000,$A12,Datos!$C$2:$C$5000,$B12,Datos!$D$2:$D$5000,I$2)) | J12: =IF(COUNTIFS(Datos!$A$2:$A$5000,J$1,Datos!$B$2:$B$5000,$A12,Datos!$C$2:$C$5000,$B12,Datos!$D$2:$D$5000,J$2)=0,"",SUMIFS(Datos!$E$2:$E$5000,Datos!$A$2:$A$5000,J$1,Datos!$B$2:$B$5000,$A12,Datos!$C$2:$C$5000,$B12,Datos!$D$2:$D$5000,J$2))
A13: Argentina | B13: 2006 | C13: =IF(COUNTIFS(Datos!$A$2:$A$5000,C$1,Datos!$B$2:$B$5000,$A13,Datos!$C$2:$C$5000,$B13,Datos!$D$2:$D$5000,C$2)=0,"",SUMIFS(Datos!$E$2:$E$5000,Datos!$A$2:$A$5000,C$1,Datos!$B$2:$B$5000,$A13,Datos!$C$2:$C$5000,$B13,Datos!$D$2:$D$5000,C$2)) | D13: =IF(COUNTIFS(Datos!$A$2:$A$5000,D$1,Datos!$B$2:$B$5000,$A13,Datos!$C$2:$C$5000,$B13,Datos!$D$2:$D$5000,D$2)=0,"",SUMIFS(Datos!$E$2:$E$5000,Datos!$A$2:$A$5000,D$1,Datos!$B$2:$B$5000,$A13,Datos!$C$2:$C$5000,$B13,Datos!$D$2:$D$5000,D$2)) | E13: =IF(COUNTIFS(Datos!$A$2:$A$5000,E$1,Datos!$B$2:$B$5000,$A13,Datos!$C$2:$C$5000,$B13,Datos!$D$2:$D$5000,E$2)=0,"",SUMIFS(Datos!$E$2:$E$5000,Datos!$A$2:$A$5000,E$1,Datos!$B$2:$B$5000,$A13,Datos!$C$2:$C$5000,$B13,Datos!$D$2:$D$5000,E$2)) | F13: =IF(COUNTIFS(Datos!$A$2:$A$5000,F$1,Datos!$B$2:$B$5000,$A13,Datos!$C$2:$C$5000,$B13,Datos!$D$2:$D$5000,F$2)=0,"",SUMIFS(Datos!$E$2:$E$5000,Datos!$A$2:$A$5000,F$1,Datos!$B$2:$B$5000,$A13,Datos!$C$2:$C$5000,$B13,Datos!$D$2:$D$5000,F$2)) | G13: =IF(COUNTIFS(Datos!$A$2:$A$5000,G$1,Datos!$B$2:$B$5000,$A13,Datos!$C$2:$C$5000,$B13,Datos!$D$2:$D$5000,G$2)=0,"",SUMIFS(Datos!$E$2:$E$5000,Datos!$A$2:$A$5000,G$1,Datos!$B$2:$B$5000,$A13,Datos!$C$2:$C$5000,$B13,Datos!$D$2:$D$5000,G$2)) | H13: =IF(COUNTIFS(Datos!$A$2:$A$5000,H$1,Datos!$B$2:$B$5000,$A13,Datos!$C$2:$C$5000,$B13,Datos!$D$2:$D$5000,H$2)=0,"",SUMIFS(Datos!$E$2:$E$5000,Datos!$A$2:$A$5000,H$1,Datos!$B$2:$B$5000,$A13,Datos!$C$2:$C$5000,$B13,Datos!$D$2:$D$5000,H$2)) | I13: =IF(COUNTIFS(Datos!$A$2:$A$5000,I$1,Datos!$B$2:$B$5000,$A13,Datos!$C$2:$C$5000,$B13,Datos!$D$2:$D$5000,I$2)=0,"",SUMIFS(Datos!$E$2:$E$5000,Datos!$A$2:$A$5000,I$1,Datos!$B$2:$B$5000,$A13,Datos!$C$2:$C$5000,$B13,Datos!$D$2:$D$5000,I$2)) | J13: =IF(COUNTIFS(Datos!$A$2:$A$5000,J$1,Datos!$B$2:$B$5000,$A13,Datos!$C$2:$C$5000,$B13,Datos!$D$2:$D$5000,J$2)=0,"",SUMIFS(Datos!$E$2:$E$5000,Datos!$A$2:$A$5000,J$1,Datos!$B$2:$B$5000,$A13,Datos!$C$2:$C$5000,$B13,Datos!$D$2:$D$5000,J$2))
A14: Argentina | B14: 2007 | C14: =IF(COUNTIFS(Datos!$A$2:$A$5000,C$1,Datos!$B$2:$B$5000,$A14,Datos!$C$2:$C$5000,$B14,Datos!$D$2:$D$5000,C$2)=0,"",SUMIFS(Datos!$E$2:$E$5000,Datos!$A$2:$A$5000,C$1,Datos!$B$2:$B$5000,$A14,Datos!$C$2:$C$5000,$B14,Datos!$D$2:$D$5000,C$2)) | D14: =IF(COUNTIFS(Datos!$A$2:$A$5000,D$1,Datos!$B$2:$B$5000,$A14,Datos!$C$2:$C$5000,$B14,Datos!$D$2:$D$5000,D$2)=0,"",SUMIFS(Datos!$E$2:$E$5000,Datos!$A$2:$A$5000,D$1,Datos!$B$2:$B$5000,$A14,Datos!$C$2:$C$5000,$B14,Datos!$D$2:$D$5000,D$2)) | E14: =IF(COUNTIFS(Datos!$A$2:$A$5000,E$1,Datos!$B$2:$B$5000,$A14,Datos!$C$2:$C$5000,$B14,Datos!$D$2:$D$5000,E$2)=0,"",SUMIFS(Datos!$E$2:$E$5000,Datos!$A$2:$A$5000,E$1,Datos!$B$2:$B$5000,$A14,Datos!$C$2:$C$5000,$B14,Datos!$D$2:$D$5000,E$2)) | F14: =IF(COUNTIFS(Datos!$A$2:$A$5000,F$1,Datos!$B$2:$B$5000,$A14,Datos!$C$2:$C$5000,$B14,Datos!$D$2:$D$5000,F$2)=0,"",SUMIFS(Datos!$E$2:$E$5000,Datos!$A$2:$A$5000,F$1,Datos!$B$2:$B$5000,$A14,Datos!$C$2:$C$5000,$B14,Datos!$D$2:$D$5000,F$2)) | G14: =IF(COUNTIFS(Datos!$A$2:$A$5000,G$1,Datos!$B$2:$B$5000,$A14,Datos!$C$2:$C$5000,$B14,Datos!$D$2:$D$5000,G$2)=0,"",SUMIFS(Datos!$E$2:$E$5000,Datos!$A$2:$A$5000,G$1,Datos!$B$2:$B$5000,$A14,Datos!$C$2:$C$5000,$B14,Datos!$D$2:$D$5000,G$2)) | H14: =IF(COUNTIFS(Datos!$A$2:$A$5000,H$1,Datos!$B$2:$B$5000,$A14,Datos!$C$2:$C$5000,$B14,Datos!$D$2:$D$5000,H$2)=0,"",SUMIFS(Datos!$E$2:$E$5000,Datos!$A$2:$A$5000,H$1,Datos!$B$2:$B$5000,$A14,Datos!$C$2:$C$5000,$B14,Datos!$D$2:$D$5000,H$2)) | I14: =IF(COUNTIFS(Datos!$A$2:$A$5000,I$1,Datos!$B$2:$B$5000,$A14,Datos!$C$2:$C$5000,$B14,Datos!$D$2:$D$5000,I$2)=0,"",SUMIFS(Datos!$E$2:$E$5000,Datos!$A$2:$A$5000,I$1,Datos!$B$2:$B$5000,$A14,Datos!$C$2:$C$5000,$B14,Datos!$D$2:$D$5000,I$2)) | J14: =IF(COUNTIFS(Datos!$A$2:$A$5000,J$1,Datos!$B$2:$B$5000,$A14,Datos!$C$2:$C$5000,$B14,Datos!$D$2:$D$5000,J$2)=0,"",SUMIFS(Datos!$E$2:$E$5000,Datos!$A$2:$A$5000,J$1,Datos!$B$2:$B$5000,$A14,Datos!$C$2:$C$5000,$B14,Datos!$D$2:$D$5000,J$2))
... A378: Venezuela | B378: 2024 | C378: =IF(COUNTIFS(Datos!$A$2:$A$5000,C$1,Datos!$B$2:$B$5000,$A378,Datos!$C$2:$C$5000,$B378,Datos!$D$2:$D$5000,C$2)=0,"",SUMIFS(Datos!$E$2:$E$5000,Datos!$A$2:$A$5000,C$1,Datos!$B$2:$B$5000,$A378,Datos!$C$2:$C$5000,$B378,Datos!$D$2:$D$5000,C$2)) | D378: =IF(COUNTIFS(Datos!$A$2:$A$5000,D$1,Datos!$B$2:$B$5000,$A378,Datos!$C$2:$C$5000,$B378,Datos!$D$2:$D$5000,D$2)=0,"",SUMIFS(Datos!$E$2:$E$5000,Datos!$A$2:$A$5000,D$1,Datos!$B$2:$B$5000,$A378,Datos!$C$2:$C$5000,$B378,Datos!$D$2:$D$5000,D$2)) | E378: =IF(COUNTIFS(Datos!$A$2:$A$5000,E$1,Datos!$B$2:$B$5000,$A378,Datos!$C$2:$C$5000,$B378,Datos!$D$2:$D$5000,E$2)=0,"",SUMIFS(Datos!$E$2:$E$5000,Datos!$A$2:$A$5000,E$1,Datos!$B$2:$B$5000,$A378,Datos!$C$2:$C$5000,$B378,Datos!$D$2:$D$5000,E$2)) | F378: =IF(COUNTIFS(Datos!$A$2:$A$5000,F$1,Datos!$B$2:$B$5000,$A378,Datos!$C$2:$C$5000,$B378,Datos!$D$2:$D$5000,F$2)=0,"",SUMIFS(Datos!$E$2:$E$5000,Datos!$A$2:$A$5000,F$1,Datos!$B$2:$B$5000,$A378,Datos!$C$2:$C$5000,$B378,Datos!$D$2:$D$5000,F$2)) | G378: =IF(COUNTIFS(Datos!$A$2:$A$5000,G$1,Datos!$B$2:$B$5000,$A378,Datos!$C$2:$C$5000,$B378,Datos!$D$2:$D$5000,G$2)=0,"",SUMIFS(Datos!$E$2:$E$5000,Datos!$A$2:$A$5000,G$1,Datos!$B$2:$B$5000,$A378,Datos!$C$2:$C$5000,$B378,Datos!$D$2:$D$5000,G$2)) | H378: =IF(COUNTIFS(Datos!$A$2:$A$5000,H$1,Datos!$B$2:$B$5000,$A378,Datos!$C$2:$C$5000,$B378,Datos!$D$2:$D$5000,H$2)=0,"",SUMIFS(Datos!$E$2:$E$5000,Datos!$A$2:$A$5000,H$1,Datos!$B$2:$B$5000,$A378,Datos!$C$2:$C$5000,$B378,Datos!$D$2:$D$5000,H$2)) | I378: =IF(COUNTIFS(Datos!$A$2:$A$5000,I$1,Datos!$B$2:$B$5000,$A378,Datos!$C$2:$C$5000,$B378,Datos!$D$2:$D$5000,I$2)=0,"",SUMIFS(Datos!$E$2:$E$5000,Datos!$A$2:$A$5000,I$1,Datos!$B$2:$B$5000,$A378,Datos!$C$2:$C$5000,$B378,Datos!$D$2:$D$5000,I$2)) | J378: =IF(COUNTIFS(Datos!$A$2:$A$5000,J$1,Datos!$B$2:$B$5000,$A378,Datos!$C$2:$C$5000,$B378,Datos!$D$2:$D$5000,J$2)=0,"",SUMIFS(Datos!$E$2:$E$5000,Datos!$A$2:$A$5000,J$1,Datos!$B$2:$B$5000,$A378,Datos!$C$2:$C$5000,$B378,Datos!$D$2:$D$5000,J$2))

Sheet Gini
A1: País | B1: Año | C1: Gini (0-100) | D1: Fuente | E1: Clave
A2: Argentina | B2: 1995 | E2: =A2&"|"&B2
A3: Argentina | B3: 1996 | E3: =A3&"|"&B3
A4: Argentina | B4: 1997 | E4: =A4&"|"&B4
A5: Argentina | B5: 1998 | E5: =A5&"|"&B5
A6: Argentina | B6: 2000 | E6: =A6&"|"&B6
A7: Argentina | B7: 2001 | E7: =A7&"|"&B7
A8: Argentina | B8: 2002 | E8: =A8&"|"&B8
A9: Argentina | B9: 2003 | E9: =A9&"|"&B9
A10: Argentina | B10: 2004 | E10: =A10&"|"&B10
A11: Argentina | B11: 2005 | E11: =A11&"|"&B11
A12: Argentina | B12: 2006 | E12: =A12&"|"&B12
A13: Argentina | B13: 2007 | E13: =A13&"|"&B13
... A377: Venezuela | B377: 2024 | E377: =A377&"|"&B377

Sheet Puente_CPI
A1: País (HDX) | B1: ISO3 | C1: CPI 2011 datahub (0-10) | D1: CPI 2012 HDX (0-100) | F1: Coeficientes del empalme | G1: Valor
A2: Afghanistan | B2: AFG | C2: 1.517 | D2: 8 | F2: Intercepto (a) | G2: =INTERCEPT($D$2:$D$177,$C$2:$C$177)
A3: Albania | B3: ALB | C3: 3.053 | D3: 33 | F3: Pendiente (b) | G3: =SLOPE($D$2:$D$177,$C$2:$C$177)
A4: Algeria | B4: DZA | C4: 2.904 | D4: 34 | F4: R cuadrado | G4: =RSQ($D$2:$D$177,$C$2:$C$177)
A5: Angola | B5: AGO | C5: 2.005 | D5: 22 | F5: N países | G5: =COUNT($C$2:$C$177)
A6: Argentina | B6: ARG | C6: 2.996 | D6: 35
A7: Armenia | B7: ARM | C7: 2.629 | D7: 34 | F7: CPI empalmado (años <= 2011) = a + b x CPI datahub (0-10). Desde 2012: CPI HDX sin cambios.
A8: Australia | B8: AUS | C8: 8.844 | D8: 85 | F8: Supuesto: la corrupción percibida no cambió realmente entre 2011 y 2012; la diferencia se atribuye al cambio de metodología.
A9: Austria | B9: AUT | C9: 7.787 | D9: 69
A10: Azerbaijan | B10: AZE | C10: 2.375 | D10: 27
A11: Bahamas | B11: BHS | C11: 7.289 | D11: 71
A12: Bahrain | B12: BHR | C12: 5.11 | D12: 51
A13: Bangladesh | B13: BGD | C13: 2.657 | D13: 26
A14: Barbados | B14: BRB | C14: 7.774 | D14: 76
A15: Belarus | B15: BLR | C15: 2.418 | D15: 31
A16: Belgium | B16: BEL | C16: 7.487 | D16: 75
A17: Benin | B17: BEN | C17: 2.97 | D17: 36
A18: Bhutan | B18: BTN | C18: 5.742 | D18: 63
A19: Bolivia | B19: BOL | C19: 2.763 | D19: 34
A20: Bosnia and Herzegovina | B20: BIH | C20: 3.207 | D20: 42
... A177: Zimbabwe | B177: ZWE | C177: 2.23 | D177: 20

Sheet Corrupcion
A1: País | B1: Año | C1: CPI datahub (0-10, hasta 2011) | D1: CPI global HDX (0-100, desde 2012) | E1: CPI escala 0-10 (empalmado) | F1: CPI 0-100 (solo desde 2012) | G1: CPI 0-100 empalmado por regresión | H1: Clave
A2: Argentina | B2: 1995 | C2: 5.24 | E2: =IF(B2<=2011,IF(C2="","",C2),IF(D2="","",D2/10)) | F2: =IF(OR(B2<=2011,D2=""),"",D2) | G2: =IF(B2<=2011,IF(C2="","",Puente_CPI!$G$2+Puente_CPI!$G$3*C2),IF(D2="","",D2)) | H2: =A2&"|"&B2
A3: Argentina | B3: 1996 | C3: 3.41 | E3: =IF(B3<=2011,IF(C3="","",C3),IF(D3="","",D3/10)) | F3: =IF(OR(B3<=2011,D3=""),"",D3) | G3: =IF(B3<=2011,IF(C3="","",Puente_CPI!$G$2+Puente_CPI!$G$3*C3),IF(D3="","",D3)) | H3: =A3&"|"&B3
A4: Argentina | B4: 1997 | C4: 2.81 | E4: =IF(B4<=2011,IF(C4="","",C4),IF(D4="","",D4/10)) | F4: =IF(OR(B4<=2011,D4=""),"",D4) | G4: =IF(B4<=2011,IF(C4="","",Puente_CPI!$G$2+Puente_CPI!$G$3*C4),IF(D4="","",D4)) | H4: =A4&"|"&B4
A5: Argentina | B5: 1998 | C5: 3 | E5: =IF(B5<=2011,IF(C5="","",C5),IF(D5="","",D5/10)) | F5: =IF(OR(B5<=2011,D5=""),"",D5) | G5: =IF(B5<=2011,IF(C5="","",Puente_CPI!$G$2+Puente_CPI!$G$3*C5),IF(D5="","",D5)) | H5: =A5&"|"&B5
A6: Argentina | B6: 2000 | C6: 3.5 | E6: =IF(B6<=2011,IF(C6="","",C6),IF(D6="","",D6/10)) | F6: =IF(OR(B6<=2011,D6=""),"",D6) | G6: =IF(B6<=2011,IF(C6="","",Puente_CPI!$G$2+Puente_CPI!$G$3*C6),IF(D6="","",D6)) | H6: =A6&"|"&B6
A7: Argentina | B7: 2001 | C7: 3.5 | E7: =IF(B7<=2011,IF(C7="","",C7),IF(D7="","",D7/10)) | F7: =IF(OR(B7<=2011,D7=""),"",D7) | G7: =IF(B7<=2011,IF(C7="","",Puente_CPI!$G$2+Puente_CPI!$G$3*C7),IF(D7="","",D7)) | H7: =A7&"|"&B7
A8: Argentina | B8: 2002 | C8: 2.8 | E8: =IF(B8<=2011,IF(C8="","",C8),IF(D8="","",D8/10)) | F8: =IF(OR(B8<=2011,D8=""),"",D8) | G8: =IF(B8<=2011,IF(C8="","",Puente_CPI!$G$2+Puente_CPI!$G$3*C8),IF(D8="","",D8)) | H8: =A8&"|"&B8
A9: Argentina | B9: 2003 | C9: 2.5 | E9: =IF(B9<=2011,IF(C9="","",C9),IF(D9="","",D9/10)) | F9: =IF(OR(B9<=2011,D9=""),"",D9) | G9: =IF(B9<=2011,IF(C9="","",Puente_CPI!$G$2+Puente_CPI!$G$3*C9),IF(D9="","",D9)) | H9: =A9&"|"&B9
A10: Argentina | B10: 2004 | C10: 2.5 | E10: =IF(B10<=2011,IF(C10="","",C10),IF(D10="","",D10/10)) | F10: =IF(OR(B10<=2011,D10=""),"",D10) | G10: =IF(B10<=2011,IF(C10="","",Puente_CPI!$G$2+Puente_CPI!$G$3*C10),IF(D10="","",D10)) | H10: =A10&"|"&B10
A11: Argentina | B11: 2005 | C11: 2.8 | E11: =IF(B11<=2011,IF(C11="","",C11),IF(D11="","",D11/10)) | F11: =IF(OR(B11<=2011,D11=""),"",D11) | G11: =IF(B11<=2011,IF(C11="","",Puente_CPI!$G$2+Puente_CPI!$G$3*C11),IF(D11="","",D11)) | H11: =A11&"|"&B11
A12: Argentina | B12: 2006 | C12: 2.9 | E12: =IF(B12<=2011,IF(C12="","",C12),IF(D12="","",D12/10)) | F12: =IF(OR(B12<=2011,D12=""),"",D12) | G12: =IF(B12<=2011,IF(C12="","",Puente_CPI!$G$2+Puente_CPI!$G$3*C12),IF(D12="","",D12)) | H12: =A12&"|"&B12
A13: Argentina | B13: 2007 | C13: 2.9 | E13: =IF(B13<=2011,IF(C13="","",C13),IF(D13="","",D13/10)) | F13: =IF(OR(B13<=2011,D13=""),"",D13) | G13: =IF(B13<=2011,IF(C13="","",Puente_CPI!$G$2+Puente_CPI!$G$3*C13),IF(D13="","",D13)) | H13: =A13&"|"&B13
... A17: Argentina | B17: 2011 | C17: 2.996 | E17: =IF(B17<=2011,IF(C17="","",C17),IF(D17="","",D17/10)) | F17: =IF(OR(B17<=2011,D17=""),"",D17) | G17: =IF(B17<=2011,IF(C17="","",Puente_CPI!$G$2+Puente_CPI!$G$3*C17),IF(D17="","",D17)) | H17: =A17&"|"&B17
A18: Argentina | B18: 2015 | D18: 32 | E18: =IF(B18<=2011,IF(C18="","",C18),IF(D18="","",D18/10)) | F18: =IF(OR(B18<=2011,D18=""),"",D18) | G18: =IF(B18<=2011,IF(C18="","",Puente_CPI!$G$2+Puente_CPI!$G$3*C18),IF(D18="","",D18)) | H18: =A18&"|"&B18
A19: Argentina | B19: 2016 | D19: 36 | E19: =IF(B19<=2011,IF(C19="","",C19),IF(D19="","",D19/10)) | F19: =IF(OR(B19<=2011,D19=""),"",D19) | G19: =IF(B19<=2011,IF(C19="","",Puente_CPI!$G$2+Puente_CPI!$G$3*C19),IF(D19="","",D19)) | H19: =A19&"|"&B19
A20: Argentina | B20: 2017 | D20: 39 | E20: =IF(B20<=2011,IF(C20="","",C20),IF(D20="","",D20/10)) | F20: =IF(OR(B20<=2011,D20=""),"",D20) | G20: =IF(B20<=2011,IF(C20="","",Puente_CPI!$G$2+Puente_CPI!$G$3*C20),IF(D20="","",D20)) | H20: =A20&"|"&B20
A21: Argentina | B21: 2018 | D21: 40 | E21: =IF(B21<=2011,IF(C21="","",C21),IF(D21="","",D21/10)) | F21: =IF(OR(B21<=2011,D21=""),"",D21) | G21: =IF(B21<=2011,IF(C21="","",Puente_CPI!$G$2+Puente_CPI!$G$3*C21),IF(D21="","",D21)) | H21: =A21&"|"&B21
A22: Argentina | B22: 2020 | D22: 42 | E22: =IF(B22<=2011,IF(C22="","",C22),IF(D22="","",D22/10)) | F22: =IF(OR(B22<=2011,D22=""),"",D22) | G22: =IF(B22<=2011,IF(C22="","",Puente_CPI!$G$2+Puente_CPI!$G$3*C22),IF(D22="","",D22)) | H22: =A22&"|"&B22
A23: Argentina | B23: 2024 | D23: 37 | E23: =IF(B23<=2011,IF(C23="","",C23),IF(D23="","",D23/10)) | F23: =IF(OR(B23<=2011,D23=""),"",D23) | G23: =IF(B23<=2011,IF(C23="","",Puente_CPI!$G$2+Puente_CPI!$G$3*C23),IF(D23="","",D23)) | H23: =A23&"|"&B23
A24: Bolivia | B24: 1996 | C24: 3.4 | E24: =IF(B24<=2011,IF(C24="","",C24),IF(D24="","",D24/10)) | F24: =IF(OR(B24<=2011,D24=""),"",D24) | G24: =IF(B24<=2011,IF(C24="","",Puente_CPI!$G$2+Puente_CPI!$G$3*C24),IF(D24="","",D24)) | H24: =A24&"|"&B24
A25: Bolivia | B25: 1997 | C25: 2.05 | E25: =IF(B25<=2011,IF(C25="","",C25),IF(D25="","",D25/10)) | F25: =IF(OR(B25<=2011,D25=""),"",D25) | G25: =IF(B25<=2011,IF(C25="","",Puente_CPI!$G$2+Puente_CPI!$G$3*C25),IF(D25="","",D25)) | H25: =A25&"|"&B25
A26: Bolivia | B26: 1998 | C26: 2.8 | E26: =IF(B26<=2011,IF(C26="","",C26),IF(D26="","",D26/10)) | F26: =IF(OR(B26<=2011,D26=""),"",D26) | G26: =IF(B26<=2011,IF(C26="","",Puente_CPI!$G$2+Puente_CPI!$G$3*C26),IF(D26="","",D26)) | H26: =A26&"|"&B26
A27: Bolivia | B27: 2000 | C27: 2.7 | E27: =IF(B27<=2011,IF(C27="","",C27),IF(D27="","",D27/10)) | F27: =IF(OR(B27<=2011,D27=""),"",D27) | G27: =IF(B27<=2011,IF(C27="","",Puente_CPI!$G$2+Puente_CPI!$G$3*C27),IF(D27="","",D27)) | H27: =A27&"|"&B27
A28: Bolivia | B28: 2001 | C28: 2 | E28: =IF(B28<=2011,IF(C28="","",C28),IF(D28="","",D28/10)) | F28: =IF(OR(B28<=2011,D28=""),"",D28) | G28: =IF(B28<=2011,IF(C28="","",Puente_CPI!$G$2+Puente_CPI!$G$3*C28),IF(D28="","",D28)) | H28: =A28&"|"&B28
A29: Bolivia | B29: 2002 | C29: 2.2 | E29: =IF(B29<=2011,IF(C29="","",C29),IF(D29="","",D29/10)) | F29: =IF(OR(B29<=2011,D29=""),"",D29) | G29: =IF(B29<=2011,IF(C29="","",Puente_CPI!$G$2+Puente_CPI!$G$3*C29),IF(D29="","",D29)) | H29: =A29&"|"&B29
A30: Bolivia | B30: 2003 | C30: 2.3 | E30: =IF(B30<=2011,IF(C30="","",C30),IF(D30="","",D30/10)) | F30: =IF(OR(B30<=2011,D30=""),"",D30) | G30: =IF(B30<=2011,IF(C30="","",Puente_CPI!$G$2+Puente_CPI!$G$3*C30),IF(D30="","",D30)) | H30: =A30&"|"&B30
A31: Bolivia | B31: 2004 | C31: 2.2 | E31: =IF(B31<=2011,IF(C31="","",C31),IF(D31="","",D31/10)) | F31: =IF(OR(B31<=2011,D31=""),"",D31) | G31: =IF(B31<=2011,IF(C31="","",Puente_CPI!$G$2+Puente_CPI!$G$3*C31),IF(D31="","",D31)) | H31: =A31&"|"&B31
A32: Bolivia | B32: 2005 | C32: 2.5 | E32: =IF(B32<=2011,IF(C32="","",C32),IF(D32="","",D32/10)) | F32: =IF(OR(B32<=2011,D32=""),"",D32) | G32: =IF(B32<=2011,IF(C32="","",Puente_CPI!$G$2+Puente_CPI!$G$3*C32),IF(D32="","",D32)) | H32: =A32&"|"&B32
A33: Bolivia | B33: 2006 | C33: 2.7 | E33: =IF(B33<=2011,IF(C33="","",C33),IF(D33="","",D33/10)) | F33: =IF(OR(B33<=2011,D33=""),"",D33) | G33: =IF(B33<=2011,IF(C33="","",Puente_CPI!$G$2+Puente_CPI!$G$3*C33),IF(D33="","",D33)) | H33: =A33&"|"&B33
A34: Bolivia | B34: 2007 | C34: 2.9 | E34: =IF(B34<=2011,IF(C34="","",C34),IF(D34="","",D34/10)) | F34: =IF(OR(B34<=2011,D34=""),"",D34) | G34: =IF(B34<=2011,IF(C34="","",Puente_CPI!$G$2+Puente_CPI!$G$3*C34),IF(D34="","",D34)) | H34: =A34&"|"&B34
A35: Bolivia | B35: 2008 | C35: 3 | E35: =IF(B35<=2011,IF(C35="","",C35),IF(D35="","",D35/10)) | F35: =IF(OR(B35<=2011,D35=""),"",D35) | G35: =IF(B35<=2011,IF(C35="","",Puente_CPI!$G$2+Puente_CPI!$G$3*C35),IF(D35="","",D35)) | H35: =A35&"|"&B35
... A38: Bolivia | B38: 2011 | C38: 2.763 | E38: =IF(B38<=2011,IF(C38="","",C38),IF(D38="","",D38/10)) | F38: =IF(OR(B38<=2011,D38=""),"",D38) | G38: =IF(B38<=2011,IF(C38="","",Puente_CPI!$G$2+Puente_CPI!$G$3*C38),IF(D38="","",D38)) | H38: =A38&"|"&B38
A39: Bolivia | B39: 2016 | D39: 33 | E39: =IF(B39<=2011,IF(C39="","",C39),IF(D39="","",D39/10)) | F39: =IF(OR(B39<=2011,D39=""),"",D39) | G39: =IF(B39<=2011,IF(C39="","",Puente_CPI!$G$2+Puente_CPI!$G$3*C39),IF(D39="","",D39)) | H39: =A39&"|"&B39
A40: Bolivia | B40: 2017 | D40: 33 | E40: =IF(B40<=2011,IF(C40="","",C40),IF(D40="","",D40/10)) | F40: =IF(OR(B40<=2011,D40=""),"",D40) | G40: =IF(B40<=2011,IF(C40="","",Puente_CPI!$G$2+Puente_CPI!$G$3*C40),IF(D40="","",D40)) | H40: =A40&"|"&B40
A41: Bolivia | B41: 2018 | D41: 29 | E41: =IF(B41<=2011,IF(C41="","",C41),IF(D41="","",D41/10)) | F41: =IF(OR(B41<=2011,D41=""),"",D41) | G41: =IF(B41<=2011,IF(C41="","",Puente_CPI!$G$2+Puente_CPI!$G$3*C41),IF(D41="","",D41)) | H41: =A41&"|"&B41
A42: Bolivia | B42: 2020 | D42: 31 | E42: =IF(B42<=2011,IF(C42="","",C42),IF(D42="","",D42/10)) | F42: =IF(OR(B42<=2011,D42=""),"",D42) | G42: =IF(B42<=2011,IF(C42="","",Puente_CPI!$G$2+Puente_CPI!$G$3*C42),IF(D42="","",D42)) | H42: =A42&"|"&B42
A43: Bolivia | B43: 2024 | D43: 28 | E43: =IF(B43<=2011,IF(C43="","",C43),IF(D43="","",D43/10)) | F43: =IF(OR(B43<=2011,D43=""),"",D43) | G43: =IF(B43<=2011,IF(C43="","",Puente_CPI!$G$2+Puente_CPI!$G$3*C43),IF(D43="","",D43)) | H43: =A43&"|"&B43
A44: Brasil | B44: 1995 | C44: 2.7 | E44: =IF(B44<=2011,IF(C44="","",C44),IF(D44="","",D44/10)) | F44: =IF(OR(B44<=2011,D44=""),"",D44) | G44: =IF(B44<=2011,IF(C44="","",Puente_CPI!$G$2+Puente_CPI!$G$3*C44),IF(D44="","",D44)) | H44: =A44&"|"&B44
A45: Brasil | B45: 1996 | C45: 2.96 | E45: =IF(B45<=2011,IF(C45="","",C45),IF(D45="","",D45/10)) | F45: =IF(OR(B45<=2011,D45=""),"",D45) | G45: =IF(B45<=2011,IF(C45="","",Puente_CPI!$G$2+Puente_CPI!$G$3*C45),IF(D45="","",D45)) | H45: =A45&"|"&B45
...

Sheet Panel_A
A1: País | B1: Año | C1: Y: Apoyo democracia (A) | D1: X: Grupos poderosos (A) | E1: X: Gini | F1: X: CPI escala 0-10 (empalmado) | G1: X: CPI 0-100 (desde 2012) | H1: X: CPI 0-100 empalmado por regresión | I1: Completo con CPI 0-10 (1 = usar) | J1: Completo con CPI 0-100 (1 = usar) | K1: Completo con CPI regresión (1 = usar)
A2: Argentina | B2: 1995 | C2: =IF(Categorias!C3="","",Categorias!C3) | D2: =IF(Categorias!H3="","",Categorias!H3) | E2: =IFERROR(IF(INDEX(Gini!$C$2:$C$377,MATCH($A2&"|"&$B2,Gini!$E$2:$E$377,0))="","",INDEX(Gini!$C$2:$C$377,MATCH($A2&"|"&$B2,Gini!$E$2:$E$377,0))),"") | F2: =IFERROR(IF(INDEX(Corrupcion!$E$2:$E$377,MATCH($A2&"|"&$B2,Corrupcion!$H$2:$H$377,0))="","",INDEX(Corrupcion!$E$2:$E$377,MATCH($A2&"|"&$B2,Corrupcion!$H$2:$H$377,0))),"") | G2: =IFERROR(IF(INDEX(Corrupcion!$F$2:$F$377,MATCH($A2&"|"&$B2,Corrupcion!$H$2:$H$377,0))="","",INDEX(Corrupcion!$F$2:$F$377,MATCH($A2&"|"&$B2,Corrupcion!$H$2:$H$377,0))),"") | H2: =IFERROR(IF(INDEX(Corrupcion!$G$2:$G$377,MATCH($A2&"|"&$B2,Corrupcion!$H$2:$H$377,0))="","",INDEX(Corrupcion!$G$2:$G$377,MATCH($A2&"|"&$B2,Corrupcion!$H$2:$H$377,0))),"") | I2: =IF(COUNTBLANK(C2:E2)+COUNTBLANK(F2)=0,1,0) | J2: =IF(COUNTBLANK(C2:E2)+COUNTBLANK(G2)=0,1,0) | K2: =IF(COUNTBLANK(C2:E2)+COUNTBLANK(H2)=0,1,0)
A3: Argentina | B3: 1996 | C3: =IF(Categorias!C4="","",Categorias!C4) | D3: =IF(Categorias!H4="","",Categorias!H4) | E3: =IFERROR(IF(INDEX(Gini!$C$2:$C$377,MATCH($A3&"|"&$B3,Gini!$E$2:$E$377,0))="","",INDEX(Gini!$C$2:$C$377,MATCH($A3&"|"&$B3,Gini!$E$2:$E$377,0))),"") | F3: =IFERROR(IF(INDEX(Corrupcion!$E$2:$E$377,MATCH($A3&"|"&$B3,Corrupcion!$H$2:$H$377,0))="","",INDEX(Corrupcion!$E$2:$E$377,MATCH($A3&"|"&$B3,Corrupcion!$H$2:$H$377,0))),"") | G3: =IFERROR(IF(INDEX(Corrupcion!$F$2:$F$377,MATCH($A3&"|"&$B3,Corrupcion!$H$2:$H$377,0))="","",INDEX(Corrupcion!$F$2:$F$377,MATCH($A3&"|"&$B3,Corrupcion!$H$2:$H$377,0))),"") | H3: =IFERROR(IF(INDEX(Corrupcion!$G$2:$G$377,MATCH($A3&"|"&$B3,Corrupcion!$H$2:$H$377,0))="","",INDEX(Corrupcion!$G$2:$G$377,MATCH($A3&"|"&$B3,Corrupcion!$H$2:$H$377,0))),"") | I3: =IF(COUNTBLANK(C3:E3)+COUNTBLANK(F3)=0,1,0) | J3: =IF(COUNTBLANK(C3:E3)+COUNTBLANK(G3)=0,1,0) | K3: =IF(COUNTBLANK(C3:E3)+COUNTBLANK(H3)=0,1,0)
A4: Argentina | B4: 1997 | C4: =IF(Categorias!C5="","",Categorias!C5) | D4: =IF(Categorias!H5="","",Categorias!H5) | E4: =IFERROR(IF(INDEX(Gini!$C$2:$C$377,MATCH($A4&"|"&$B4,Gini!$E$2:$E$377,0))="","",INDEX(Gini!$C$2:$C$377,MATCH($A4&"|"&$B4,Gini!$E$2:$E$377,0))),"") | F4: =IFERROR(IF(INDEX(Corrupcion!$E$2:$E$377,MATCH($A4&"|"&$B4,Corrupcion!$H$2:$H$377,0))="","",INDEX(Corrupcion!$E$2:$E$377,MATCH($A4&"|"&$B4,Corrupcion!$H$2:$H$377,0))),"") | G4: =IFERROR(IF(INDEX(Corrupcion!$F$2:$F$377,MATCH($A4&"|"&$B4,Corrupcion!$H$2:$H$377,0))="","",INDEX(Corrupcion!$F$2:$F$377,MATCH($A4&"|"&$B4,Corrupcion!$H$2:$H$377,0))),"") | H4: =IFERROR(IF(INDEX(Corrupcion!$G$2:$G$377,MATCH($A4&"|"&$B4,Corrupcion!$H$2:$H$377,0))="","",INDEX(Corrupcion!$G$2:$G$377,MATCH($A4&"|"&$B4,Corrupcion!$H$2:$H$377,0))),"") | I4: =IF(COUNTBLANK(C4:E4)+COUNTBLANK(F4)=0,1,0) | J4: =IF(COUNTBLANK(C4:E4)+COUNTBLANK(G4)=0,1,0) | K4: =IF(COUNTBLANK(C4:E4)+COUNTBLANK(H4)=0,1,0)
A5: Argentina | B5: 1998 | C5: =IF(Categorias!C6="","",Categorias!C6) | D5: =IF(Categorias!H6="","",Categorias!H6) | E5: =IFERROR(IF(INDEX(Gini!$C$2:$C$377,MATCH($A5&"|"&$B5,Gini!$E$2:$E$377,0))="","",INDEX(Gini!$C$2:$C$377,MATCH($A5&"|"&$B5,Gini!$E$2:$E$377,0))),"") | F5: =IFERROR(IF(INDEX(Corrupcion!$E$2:$E$377,MATCH($A5&"|"&$B5,Corrupcion!$H$2:$H$377,0))="","",INDEX(Corrupcion!$E$2:$E$377,MATCH($A5&"|"&$B5,Corrupcion!$H$2:$H$377,0))),"") | G5: =IFERROR(IF(INDEX(Corrupcion!$F$2:$F$377,MATCH($A5&"|"&$B5,Corrupcion!$H$2:$H$377,0))="","",INDEX(Corrupcion!$F$2:$F$377,MATCH($A5&"|"&$B5,Corrupcion!$H$2:$H$377,0))),"") | H5: =IFERROR(IF(INDEX(Corrupcion!$G$2:$G$377,MATCH($A5&"|"&$B5,Corrupcion!$H$2:$H$377,0))="","",INDEX(Corrupcion!$G$2:$G$377,MATCH($A5&"|"&$B5,Corrupcion!$H$2:$H$377,0))),"") | I5: =IF(COUNTBLANK(C5:E5)+COUNTBLANK(F5)=0,1,0) | J5: =IF(COUNTBLANK(C5:E5)+COUNTBLANK(G5)=0,1,0) | K5: =IF(COUNTBLANK(C5:E5)+COUNTBLANK(H5)=0,1,0)
A6: Argentina | B6: 2000 | C6: =IF(Categorias!C7="","",Categorias!C7) | D6: =IF(Categorias!H7="","",Categorias!H7) | E6: =IFERROR(IF(INDEX(Gini!$C$2:$C$377,MATCH($A6&"|"&$B6,Gini!$E$2:$E$377,0))="","",INDEX(Gini!$C$2:$C$377,MATCH($A6&"|"&$B6,Gini!$E$2:$E$377,0))),"") | F6: =IFERROR(IF(INDEX(Corrupcion!$E$2:$E$377,MATCH($A6&"|"&$B6,Corrupcion!$H$2:$H$377,0))="","",INDEX(Corrupcion!$E$2:$E$377,MATCH($A6&"|"&$B6,Corrupcion!$H$2:$H$377,0))),"") | G6: =IFERROR(IF(INDEX(Corrupcion!$F$2:$F$377,MATCH($A6&"|"&$B6,Corrupcion!$H$2:$H$377,0))="","",INDEX(Corrupcion!$F$2:$F$377,MATCH($A6&"|"&$B6,Corrupcion!$H$2:$H$377,0))),"") | H6: =IFERROR(IF(INDEX(Corrupcion!$G$2:$G$377,MATCH($A6&"|"&$B6,Corrupcion!$H$2:$H$377,0))="","",INDEX(Corrupcion!$G$2:$G$377,MATCH($A6&"|"&$B6,Corrupcion!$H$2:$H$377,0))),"") | I6: =IF(COUNTBLANK(C6:E6)+COUNTBLANK(F6)=0,1,0) | J6: =IF(COUNTBLANK(C6:E6)+COUNTBLANK(G6)=0,1,0) | K6: =IF(COUNTBLANK(C6:E6)+COUNTBLANK(H6)=0,1,0)
A7: Argentina | B7: 2001 | C7: =IF(Categorias!C8="","",Categorias!C8) | D7: =IF(Categorias!H8="","",Categorias!H8) | E7: =IFERROR(IF(INDEX(Gini!$C$2:$C$377,MATCH($A7&"|"&$B7,Gini!$E$2:$E$377,0))="","",INDEX(Gini!$C$2:$C$377,MATCH($A7&"|"&$B7,Gini!$E$2:$E$377,0))),"") | F7: =IFERROR(IF(INDEX(Corrupcion!$E$2:$E$377,MATCH($A7&"|"&$B7,Corrupcion!$H$2:$H$377,0))="","",INDEX(Corrupcion!$E$2:$E$377,MATCH($A7&"|"&$B7,Corrupcion!$H$2:$H$377,0))),"") | G7: =IFERROR(IF(INDEX(Corrupcion!$F$2:$F$377,MATCH($A7&"|"&$B7,Corrupcion!$H$2:$H$377,0))="","",INDEX(Corrupcion!$F$2:$F$377,MATCH($A7&"|"&$B7,Corrupcion!$H$2:$H$377,0))),"") | H7: =IFERROR(IF(INDEX(Corrupcion!$G$2:$G$377,MATCH($A7&"|"&$B7,Corrupcion!$H$2:$H$377,0))="","",INDEX(Corrupcion!$G$2:$G$377,MATCH($A7&"|"&$B7,Corrupcion!$H$2:$H$377,0))),"") | I7: =IF(COUNTBLANK(C7:E7)+COUNTBLANK(F7)=0,1,0) | J7: =IF(COUNTBLANK(C7:E7)+COUNTBLANK(G7)=0,1,0) | K7: =IF(COUNTBLANK(C7:E7)+COUNTBLANK(H7)=0,1,0)
A8: Argentina | B8: 2002 | C8: =IF(Categorias!C9="","",Categorias!C9) | D8: =IF(Categorias!H9="","",Categorias!H9) | E8: =IFERROR(IF(INDEX(Gini!$C$2:$C$377,MATCH($A8&"|"&$B8,Gini!$E$2:$E$377,0))="","",INDEX(Gini!$C$2:$C$377,MATCH($A8&"|"&$B8,Gini!$E$2:$E$377,0))),"") | F8: =IFERROR(IF(INDEX(Corrupcion!$E$2:$E$377,MATCH($A8&"|"&$B8,Corrupcion!$H$2:$H$377,0))="","",INDEX(Corrupcion!$E$2:$E$377,MATCH($A8&"|"&$B8,Corrupcion!$H$2:$H$377,0))),"") | G8: =IFERROR(IF(INDEX(Corrupcion!$F$2:$F$377,MATCH($A8&"|"&$B8,Corrupcion!$H$2:$H$377,0))="","",INDEX(Corrupcion!$F$2:$F$377,MATCH($A8&"|"&$B8,Corrupcion!$H$2:$H$377,0))),"") | H8: =IFERROR(IF(INDEX(Corrupcion!$G$2:$G$377,MATCH($A8&"|"&$B8,Corrupcion!$H$2:$H$377,0))="","",INDEX(Corrupcion!$G$2:$G$377,MATCH($A8&"|"&$B8,Corrupcion!$H$2:$H$377,0))),"") | I8: =IF(COUNTBLANK(C8:E8)+COUNTBLANK(F8)=0,1,0) | J8: =IF(COUNTBLANK(C8:E8)+COUNTBLANK(G8)=0,1,0) | K8: =IF(COUNTBLANK(C8:E8)+COUNTBLANK(H8)=0,1,0)
A9: Argentina | B9: 2003 | C9: =IF(Categorias!C10="","",Categorias!C10) | D9: =IF(Categorias!H10="","",Categorias!H10) | E9: =IFERROR(IF(INDEX(Gini!$C$2:$C$377,MATCH($A9&"|"&$B9,Gini!$E$2:$E$377,0))="","",INDEX(Gini!$C$2:$C$377,MATCH($A9&"|"&$B9,Gini!$E$2:$E$377,0))),"") | F9: =IFERROR(IF(INDEX(Corrupcion!$E$2:$E$377,MATCH($A9&"|"&$B9,Corrupcion!$H$2:$H$377,0))="","",INDEX(Corrupcion!$E$2:$E$377,MATCH($A9&"|"&$B9,Corrupcion!$H$2:$H$377,0))),"") | G9: =IFERROR(IF(INDEX(Corrupcion!$F$2:$F$377,MATCH($A9&"|"&$B9,Corrupcion!$H$2:$H$377,0))="","",INDEX(Corrupcion!$F$2:$F$377,MATCH($A9&"|"&$B9,Corrupcion!$H$2:$H$377,0))),"") | H9: =IFERROR(IF(INDEX(Corrupcion!$G$2:$G$377,MATCH($A9&"|"&$B9,Corrupcion!$H$2:$H$377,0))="","",INDEX(Corrupcion!$G$2:$G$377,MATCH($A9&"|"&$B9,Corrupcion!$H$2:$H$377,0))),"") | I9: =IF(COUNTBLANK(C9:E9)+COUNTBLANK(F9)=0,1,0) | J9: =IF(COUNTBLANK(C9:E9)+COUNTBLANK(G9)=0,1,0) | K9: =IF(COUNTBLANK(C9:E9)+COUNTBLANK(H9)=0,1,0)
A10: Argentina | B10: 2004 | C10: =IF(Categorias!C11="","",Categorias!C11) | D10: =IF(Categorias!H11="","",Categorias!H11) | E10: =IFERROR(IF(INDEX(Gini!$C$2:$C$377,MATCH($A10&"|"&$B10,Gini!$E$2:$E$377,0))="","",INDEX(Gini!$C$2:$C$377,MATCH($A10&"|"&$B10,Gini!$E$2:$E$377,0))),"") | F10: =IFERROR(IF(INDEX(Corrupcion!$E$2:$E$377,MATCH($A10&"|"&$B10,Corrupcion!$H$2:$H$377,0))="","",INDEX(Corrupcion!$E$2:$E$377,MATCH($A10&"|"&$B10,Corrupcion!$H$2:$H$377,0))),"") | G10: =IFERROR(IF(INDEX(Corrupcion!$F$2:$F$377,MATCH($A10&"|"&$B10,Corrupcion!$H$2:$H$377,0))="","",INDEX(Corrupcion!$F$2:$F$377,MATCH($A10&"|"&$B10,Corrupcion!$H$2:$H$377,0))),"") | H10: =IFERROR(IF(INDEX(Corrupcion!$G$2:$G$377,MATCH($A10&"|"&$B10,Corrupcion!$H$2:$H$377,0))="","",INDEX(Corrupcion!$G$2:$G$377,MATCH($A10&"|"&$B10,Corrupcion!$H$2:$H$377,0))),"") | I10: =IF(COUNTBLANK(C10:E10)+COUNTBLANK(F10)=0,1,0) | J10: =IF(COUNTBLANK(C10:E10)+COUNTBLANK(G10)=0,1,0) | K10: =IF(COUNTBLANK(C10:E10)+COUNTBLANK(H10)=0,1,0)
A11: Argentina | B11: 2005 | C11: =IF(Categorias!C12="","",Categorias!C12) | D11: =IF(Categorias!H12="","",Categorias!H12) | E11: =IFERROR(IF(INDEX(Gini!$C$2:$C$377,MATCH($A11&"|"&$B11,Gini!$E$2:$E$377,0))="","",INDEX(Gini!$C$2:$C$377,MATCH($A11&"|"&$B11,Gini!$E$2:$E$377,0))),"") | F11: =IFERROR(IF(INDEX(Corrupcion!$E$2:$E$377,MATCH($A11&"|"&$B11,Corrupcion!$H$2:$H$377,0))="","",INDEX(Corrupcion!$E$2:$E$377,MATCH($A11&"|"&$B11,Corrupcion!$H$2:$H$377,0))),"") | G11: =IFERROR(IF(INDEX(Corrupcion!$F$2:$F$377,MATCH($A11&"|"&$B11,Corrupcion!$H$2:$H$377,0))="","",INDEX(Corrupcion!$F$2:$F$377,MATCH($A11&"|"&$B11,Corrupcion!$H$2:$H$377,0))),"") | H11: =IFERROR(IF(INDEX(Corrupcion!$G$2:$G$377,MATCH($A11&"|"&$B11,Corrupcion!$H$2:$H$377,0))="","",INDEX(Corrupcion!$G$2:$G$377,MATCH($A11&"|"&$B11,Corrupcion!$H$2:$H$377,0))),"") | I11: =IF(COUNTBLANK(C11:E11)+COUNTBLANK(F11)=0,1,0) | J11: =IF(COUNTBLANK(C11:E11)+COUNTBLANK(G11)=0,1,0) | K11: =IF(COUNTBLANK(C11:E11)+COUNTBLANK(H11)=0,1,0)
A12: Argentina | B12: 2006 | C12: =IF(Categorias!C13="","",Categorias!C13) | D12: =IF(Categorias!H13="","",Categorias!H13) | E12: =IFERROR(IF(INDEX(Gini!$C$2:$C$377,MATCH($A12&"|"&$B12,Gini!$E$2:$E$377,0))="","",INDEX(Gini!$C$2:$C$377,MATCH($A12&"|"&$B12,Gini!$E$2:$E$377,0))),"") | F12: =IFERROR(IF(INDEX(Corrupcion!$E$2:$E$377,MATCH($A12&"|"&$B12,Corrupcion!$H$2:$H$377,0))="","",INDEX(Corrupcion!$E$2:$E$377,MATCH($A12&"|"&$B12,Corrupcion!$H$2:$H$377,0))),"") | G12: =IFERROR(IF(INDEX(Corrupcion!$F$2:$F$377,MATCH($A12&"|"&$B12,Corrupcion!$H$2:$H$377,0))="","",INDEX(Corrupcion!$F$2:$F$377,MATCH($A12&"|"&$B12,Corrupcion!$H$2:$H$377,0))),"") | H12: =IFERROR(IF(INDEX(Corrupcion!$G$2:$G$377,MATCH($A12&"|"&$B12,Corrupcion!$H$2:$H$377,0))="","",INDEX(Corrupcion!$G$2:$G$377,MATCH($A12&"|"&$B12,Corrupcion!$H$2:$H$377,0))),"") | I12: =IF(COUNTBLANK(C12:E12)+COUNTBLANK(F12)=0,1,0) | J12: =IF(COUNTBLANK(C12:E12)+COUNTBLANK(G12)=0,1,0) | K12: =IF(COUNTBLANK(C12:E12)+COUNTBLANK(H12)=0,1,0)
A13: Argentina | B13: 2007 | C13: =IF(Categorias!C14="","",Categorias!C14) | D13: =IF(Categorias!H14="","",Categorias!H14) | E13: =IFERROR(IF(INDEX(Gini!$C$2:$C$377,MATCH($A13&"|"&$B13,Gini!$E$2:$E$377,0))="","",INDEX(Gini!$C$2:$C$377,MATCH($A13&"|"&$B13,Gini!$E$2:$E$377,0))),"") | F13: =IFERROR(IF(INDEX(Corrupcion!$E$2:$E$377,MATCH($A13&"|"&$B13,Corrupcion!$H$2:$H$377,0))="","",INDEX(Corrupcion!$E$2:$E$377,MATCH($A13&"|"&$B13,Corrupcion!$H$2:$H$377,0))),"") | G13: =IFERROR(IF(INDEX(Corrupcion!$F$2:$F$377,MATCH($A13&"|"&$B13,Corrupcion!$H$2:$H$377,0))="","",INDEX(Corrupcion!$F$2:$F$377,MATCH($A13&"|"&$B13,Corrupcion!$H$2:$H$377,0))),"") | H13: =IFERROR(IF(INDEX(Corrupcion!$G$2:$G$377,MATCH($A13&"|"&$B13,Corrupcion!$H$2:$H$377,0))="","",INDEX(Corrupcion!$G$2:$G$377,MATCH($A13&"|"&$B13,Corrupcion!$H$2:$H$377,0))),"") | I13: =IF(COUNTBLANK(C13:E13)+COUNTBLANK(F13)=0,1,0) | J13: =IF(COUNTBLANK(C13:E13)+COUNTBLANK(G13)=0,1,0) | K13: =IF(COUNTBLANK(C13:E13)+COUNTBLANK(H13)=0,1,0)
... A377: Venezuela | B377: 2024 | C377: =IF(Categorias!C378="","",Categorias!C378) | D377: =IF(Categorias!H378="","",Categorias!H378) | E377: =IFERROR(IF(INDEX(Gini!$C$2:$C$377,MATCH($A377&"|"&$B377,Gini!$E$2:$E$377,0))="","",INDEX(Gini!$C$2:$C$377,MATCH($A377&"|"&$B377,Gini!$E$2:$E$377,0))),"") | F377: =IFERROR(IF(INDEX(Corrupcion!$E$2:$E$377,MATCH($A377&"|"&$B377,Corrupcion!$H$2:$H$377,0))="","",INDEX(Corrupcion!$E$2:$E$377,MATCH($A377&"|"&$B377,Corrupcion!$H$2:$H$377,0))),"") | G377: =IFERROR(IF(INDEX(Corrupcion!$F$2:$F$377,MATCH($A377&"|"&$B377,Corrupcion!$H$2:$H$377,0))="","",INDEX(Corrupcion!$F$2:$F$377,MATCH($A377&"|"&$B377,Corrupcion!$H$2:$H$377,0))),"") | H377: =IFERROR(IF(INDEX(Corrupcion!$G$2:$G$377,MATCH($A377&"|"&$B377,Corrupcion!$H$2:$H$377,0))="","",INDEX(Corrupcion!$G$2:$G$377,MATCH($A377&"|"&$B377,Corrupcion!$H$2:$H$377,0))),"") | I377: =IF(COUNTBLANK(C377:E377)+COUNTBLANK(F377)=0,1,0) | J377: =IF(COUNTBLANK(C377:E377)+COUNTBLANK(G377)=0,1,0) | K377: =IF(COUNTBLANK(C377:E377)+COUNTBLANK(H377)=0,1,0)

Sheet Panel_B
A1: País | B1: Año | C1: Y: Apoyo democracia (B) | D1: X: Grupos poderosos (B) | E1: X: Gini | F1: X: CPI escala 0-10 (empalmado) | G1: X: CPI 0-100 (desde 2012) | H1: X: CPI 0-100 empalmado por regresión | I1: Completo con CPI 0-10 (1 = usar) | J1: Completo con CPI 0-100 (1 = usar) | K1: Completo con CPI regresión (1 = usar)
A2: Argentina | B2: 1995 | C2: =IF(Categorias!C3="","",Categorias!C3/(N(Categorias!C3)+N(Categorias!D3)+N(Categorias!E3))) | D2: =IF(Categorias!H3="","",Categorias!H3/(N(Categorias!H3)+N(Categorias!I3))) | E2: =IFERROR(IF(INDEX(Gini!$C$2:$C$377,MATCH($A2&"|"&$B2,Gini!$E$2:$E$377,0))="","",INDEX(Gini!$C$2:$C$377,MATCH($A2&"|"&$B2,Gini!$E$2:$E$377,0))),"") | F2: =IFERROR(IF(INDEX(Corrupcion!$E$2:$E$377,MATCH($A2&"|"&$B2,Corrupcion!$H$2:$H$377,0))="","",INDEX(Corrupcion!$E$2:$E$377,MATCH($A2&"|"&$B2,Corrupcion!$H$2:$H$377,0))),"") | G2: =IFERROR(IF(INDEX(Corrupcion!$F$2:$F$377,MATCH($A2&"|"&$B2,Corrupcion!$H$2:$H$377,0))="","",INDEX(Corrupcion!$F$2:$F$377,MATCH($A2&"|"&$B2,Corrupcion!$H$2:$H$377,0))),"") | H2: =IFERROR(IF(INDEX(Corrupcion!$G$2:$G$377,MATCH($A2&"|"&$B2,Corrupcion!$H$2:$H$377,0))="","",INDEX(Corrupcion!$G$2:$G$377,MATCH($A2&"|"&$B2,Corrupcion!$H$2:$H$377,0))),"") | I2: =IF(COUNTBLANK(C2:E2)+COUNTBLANK(F2)=0,1,0) | J2: =IF(COUNTBLANK(C2:E2)+COUNTBLANK(G2)=0,1,0) | K2: =IF(COUNTBLANK(C2:E2)+COUNTBLANK(H2)=0,1,0)
A3: Argentina | B3: 1996 | C3: =IF(Categorias!C4="","",Categorias!C4/(N(Categorias!C4)+N(Categorias!D4)+N(Categorias!E4))) | D3: =IF(Categorias!H4="","",Categorias!H4/(N(Categorias!H4)+N(Categorias!I4))) | E3: =IFERROR(IF(INDEX(Gini!$C$2:$C$377,MATCH($A3&"|"&$B3,Gini!$E$2:$E$377,0))="","",INDEX(Gini!$C$2:$C$377,MATCH($A3&"|"&$B3,Gini!$E$2:$E$377,0))),"") | F3: =IFERROR(IF(INDEX(Corrupcion!$E$2:$E$377,MATCH($A3&"|"&$B3,Corrupcion!$H$2:$H$377,0))="","",INDEX(Corrupcion!$E$2:$E$377,MATCH($A3&"|"&$B3,Corrupcion!$H$2:$H$377,0))),"") | G3: =IFERROR(IF(INDEX(Corrupcion!$F$2:$F$377,MATCH($A3&"|"&$B3,Corrupcion!$H$2:$H$377,0))="","",INDEX(Corrupcion!$F$2:$F$377,MATCH($A3&"|"&$B3,Corrupcion!$H$2:$H$377,0))),"") | H3: =IFERROR(IF(INDEX(Corrupcion!$G$2:$G$377,MATCH($A3&"|"&$B3,Corrupcion!$H$2:$H$377,0))="","",INDEX(Corrupcion!$G$2:$G$377,MATCH($A3&"|"&$B3,Corrupcion!$H$2:$H$377,0))),"") | I3: =IF(COUNTBLANK(C3:E3)+COUNTBLANK(F3)=0,1,0) | J3: =IF(COUNTBLANK(C3:E3)+COUNTBLANK(G3)=0,1,0) | K3: =IF(COUNTBLANK(C3:E3)+COUNTBLANK(H3)=0,1,0)
A4: Argentina | B4: 1997 | C4: =IF(Categorias!C5="","",Categorias!C5/(N(Categorias!C5)+N(Categorias!D5)+N(Categorias!E5))) | D4: =IF(Categorias!H5="","",Categorias!H5/(N(Categorias!H5)+N(Categorias!I5))) | E4: =IFERROR(IF(INDEX(Gini!$C$2:$C$377,MATCH($A4&"|"&$B4,Gini!$E$2:$E$377,0))="","",INDEX(Gini!$C$2:$C$377,MATCH($A4&"|"&$B4,Gini!$E$2:$E$377,0))),"") | F4: =IFERROR(IF(INDEX(Corrupcion!$E$2:$E$377,MATCH($A4&"|"&$B4,Corrupcion!$H$2:$H$377,0))="","",INDEX(Corrupcion!$E$2:$E$377,MATCH($A4&"|"&$B4,Corrupcion!$H$2:$H$377,0))),"") | G4: =IFERROR(IF(INDEX(Corrupcion!$F$2:$F$377,MATCH($A4&"|"&$B4,Corrupcion!$H$2:$H$377,0))="","",INDEX(Corrupcion!$F$2:$F$377,MATCH($A4&"|"&$B4,Corrupcion!$H$2:$H$377,0))),"") | H4: =IFERROR(IF(INDEX(Corrupcion!$G$2:$G$377,MATCH($A4&"|"&$B4,Corrupcion!$H$2:$H$377,0))="","",INDEX(Corrupcion!$G$2:$G$377,MATCH($A4&"|"&$B4,Corrupcion!$H$2:$H$377,0))),"") | I4: =IF(COUNTBLANK(C4:E4)+COUNTBLANK(F4)=0,1,0) | J4: =IF(COUNTBLANK(C4:E4)+COUNTBLANK(G4)=0,1,0) | K4: =IF(COUNTBLANK(C4:E4)+COUNTBLANK(H4)=0,1,0)
A5: Argentina | B5: 1998 | C5: =IF(Categorias!C6="","",Categorias!C6/(N(Categorias!C6)+N(Categorias!D6)+N(Categorias!E6))) | D5: =IF(Categorias!H6="","",Categorias!H6/(N(Categorias!H6)+N(Categorias!I6))) | E5: =IFERROR(IF(INDEX(Gini!$C$2:$C$377,MATCH($A5&"|"&$B5,Gini!$E$2:$E$377,0))="","",INDEX(Gini!$C$2:$C$377,MATCH($A5&"|"&$B5,Gini!$E$2:$E$377,0))),"") | F5: =IFERROR(IF(INDEX(Corrupcion!$E$2:$E$377,MATCH($A5&"|"&$B5,Corrupcion!$H$2:$H$377,0))="","",INDEX(Corrupcion!$E$2:$E$377,MATCH($A5&"|"&$B5,Corrupcion!$H$2:$H$377,0))),"") | G5: =IFERROR(IF(INDEX(Corrupcion!$F$2:$F$377,MATCH($A5&"|"&$B5,Corrupcion!$H$2:$H$377,0))="","",INDEX(Corrupcion!$F$2:$F$377,MATCH($A5&"|"&$B5,Corrupcion!$H$2:$H$377,0))),"") | H5: =IFERROR(IF(INDEX(Corrupcion!$G$2:$G$377,MATCH($A5&"|"&$B5,Corrupcion!$H$2:$H$377,0))="","",INDEX(Corrupcion!$G$2:$G$377,MATCH($A5&"|"&$B5,Corrupcion!$H$2:$H$377,0))),"") | I5: =IF(COUNTBLANK(C5:E5)+COUNTBLANK(F5)=0,1,0) | J5: =IF(COUNTBLANK(C5:E5)+COUNTBLANK(G5)=0,1,0) | K5: =IF(COUNTBLANK(C5:E5)+COUNTBLANK(H5)=0,1,0)
A6: Argentina | B6: 2000 | C6: =IF(Categorias!C7="","",Categorias!C7/(N(Categorias!C7)+N(Categorias!D7)+N(Categorias!E7))) | D6: =IF(Categorias!H7="","",Categorias!H7/(N(Categorias!H7)+N(Categorias!I7))) | E6: =IFERROR(IF(INDEX(Gini!$C$2:$C$377,MATCH($A6&"|"&$B6,Gini!$E$2:$E$377,0))="","",INDEX(Gini!$C$2:$C$377,MATCH($A6&"|"&$B6,Gini!$E$2:$E$377,0))),"") | F6: =IFERROR(IF(INDEX(Corrupcion!$E$2:$E$377,MATCH($A6&"|"&$B6,Corrupcion!$H$2:$H$377,0))="","",INDEX(Corrupcion!$E$2:$E$377,MATCH($A6&"|"&$B6,Corrupcion!$H$2:$H$377,0))),"") | G6: =IFERROR(IF(INDEX(Corrupcion!$F$2:$F$377,MATCH($A6&"|"&$B6,Corrupcion!$H$2:$H$377,0))="","",INDEX(Corrupcion!$F$2:$F$377,MATCH($A6&"|"&$B6,Corrupcion!$H$2:$H$377,0))),"") | H6: =IFERROR(IF(INDEX(Corrupcion!$G$2:$G$377,MATCH($A6&"|"&$B6,Corrupcion!$H$2:$H$377,0))="","",INDEX(Corrupcion!$G$2:$G$377,MATCH($A6&"|"&$B6,Corrupcion!$H$2:$H$377,0))),"") | I6: =IF(COUNTBLANK(C6:E6)+COUNTBLANK(F6)=0,1,0) | J6: =IF(COUNTBLANK(C6:E6)+COUNTBLANK(G6)=0,1,0) | K6: =IF(COUNTBLANK(C6:E6)+COUNTBLANK(H6)=0,1,0)
